017-01-23 20:17:07,997 Uncaught exception: getChannelParameters() takes exactly 1 argument (0 given)
None
2017-01-23 20:17:07,998 Error type: <type 'exceptions.TypeError'>
None
2017-01-23 20:17:07,998 Traceback: ['  File "/home/uwslowcontrol/pi_db/pi_db.py", line 551, in <module>\n    channeldb = getChannelParameters()\n']
None
2017-01-23 20:18:01,248 PI_DB SCRIPT INITIALIZING...
2017-01-23 20:18:07,514 Uncaught exception: getChannelParameters() takes exactly 1 argument (0 given)
None
2017-01-23 20:18:07,514 Error type: <type 'exceptions.TypeError'>
None
2017-01-23 20:18:07,515 Traceback: ['  File "/home/uwslowcontrol/pi_db/pi_db.py", line 551, in <module>\n    channeldb = getChannelParameters()\n']
None
2017-01-23 20:19:01,786 PI_DB SCRIPT INITIALIZING...
2017-01-23 20:19:07,981 Uncaught exception: getChannelParameters() takes exactly 1 argument (0 given)
None
2017-01-23 20:19:07,981 Error type: <type 'exceptions.TypeError'>
None
2017-01-23 20:19:07,981 Traceback: ['  File "/home/uwslowcontrol/pi_db/pi_db.py", line 551, in <module>\n    channeldb = getChannelParameters()\n']
None
2017-01-23 20:20:02,245 PI_DB SCRIPT INITIALIZING...
2017-01-23 20:20:08,554 Uncaught exception: getChannelParameters() takes exactly 1 argument (0 given)
None
2017-01-23 20:20:08,554 Error type: <type 'exceptions.TypeError'>
None
2017-01-23 20:20:08,554 Traceback: ['  File "/home/uwslowcontrol/pi_db/pi_db.py", line 551, in <module>\n    channeldb = getChannelParameters()\n']
None
2017-01-23 20:21:01,810 PI_DB SCRIPT INITIALIZING...
2017-01-23 20:21:07,990 Uncaught exception: getChannelParameters() takes exactly 1 argument (0 given)
None
2017-01-23 20:21:07,991 Error type: <type 'exceptions.TypeError'>
None
2017-01-23 20:21:07,991 Traceback: ['  File "/home/uwslowcontrol/pi_db/pi_db.py", line 551, in <module>\n    channeldb = getChannelParameters()\n']
None
2017-01-23 20:21:56,564 PI_DB SCRIPT INITIALIZING...
2017-01-23 20:22:15,272 Uncaught exception: 
None
2017-01-23 20:22:15,273 Error type: <type 'exceptions.KeyboardInterrupt'>
None
2017-01-23 20:22:15,273 Traceback: ['  File "pi_db.py", line 564, in <module>\n    time.sleep(wait_time)\n']
None
2017-01-23 20:22:22,200 PI_DB SCRIPT INITIALIZING...
2017-01-26 10:04:47,138 Uncaught exception: <urlopen error [Errno 110] Connection timed out>
None
2017-01-26 10:04:47,139 Error type: <class 'urllib2.URLError'>
None
2017-01-26 10:04:47,141 Traceback: ['  File "/home/uwslowcontrol/pi_db/pi_db.py", line 551, in <module>\n    rawdata = getValues(poll_time,endpoll_time,pi_list)\n', '  File "/home/uwslowcontrol/pi_db/pi_db.py", line 302, in getValues\n    machine["data"].append(get_pi(start_time,end_time,machine_index,pi_address+address,channel_number))\n', '  File "/home/uwslowcontrol/pi_db/pi_db.py", line 290, in get_pi\n    returned_arcdata = timeseries_client.service.GetPIArchiveData(requests)\n', '  File "/usr/lib/python2.6/site-packages/suds/client.py", line 521, in __call__\n    return client.invoke(args, kwargs)\n', '  File "/usr/lib/python2.6/site-packages/suds/client.py", line 581, in invoke\n    result = self.send(soapenv)\n', '  File "/usr/lib/python2.6/site-packages/suds/client.py", line 613, in send\n    reply = self.options.transport.send(request)\n', '  File "/usr/lib/python2.6/site-packages/suds/transport/https.py", line 66, in send\n    return HttpTransport.send(self, request)\n', '  File "/usr/lib/python2.6/site-packages/suds/transport/http.py", line 82, in send\n    fp = self.u2open(u2request)\n', '  File "/usr/lib/python2.6/site-packages/suds/transport/http.py", line 132, in u2open\n    return url.open(u2request, timeout=tm)\n', '  File "/usr/lib64/python2.6/urllib2.py", line 391, in open\n    response = self._open(req, data)\n', '  File "/usr/lib64/python2.6/urllib2.py", line 409, in _open\n    \'_open\', req)\n', '  File "/usr/lib64/python2.6/urllib2.py", line 369, in _call_chain\n    result = func(*args)\n', '  File "/usr/lib64/python2.6/urllib2.py", line 1190, in http_open\n    return self.do_open(httplib.HTTPConnection, req)\n', '  File "/usr/lib64/python2.6/urllib2.py", line 1165, in do_open\n    raise URLError(err)\n']
None
2017-01-26 10:05:01,878 PI_DB SCRIPT INITIALIZING...
2017-01-26 10:06:04,916 Uncaught exception: <urlopen error [Errno 110] Connection timed out>
None
2017-01-26 10:06:04,916 Error type: <class 'urllib2.URLError'>
None
2017-01-26 10:06:04,919 Traceback: ['  File "/home/uwslowcontrol/pi_db/pi_db.py", line 269, in <module>\n    timeseries_client = Client(timeseries_url)\n', '  File "/usr/lib/python2.6/site-packages/suds/client.py", line 115, in __init__\n    self.wsdl = reader.open(url)\n', '  File "/usr/lib/python2.6/site-packages/suds/reader.py", line 150, in open\n    d = self.fn(url, self.options)\n', '  File "/usr/lib/python2.6/site-packages/suds/wsdl.py", line 136, in __init__\n    d = reader.open(url)\n', '  File "/usr/lib/python2.6/site-packages/suds/reader.py", line 74, in open\n    d = self.download(url)\n', '  File "/usr/lib/python2.6/site-packages/suds/reader.py", line 92, in download\n    fp = self.options.transport.open(Request(url))\n', '  File "/usr/lib/python2.6/site-packages/suds/transport/https.py", line 62, in open\n    return HttpTransport.open(self, request)\n', '  File "/usr/lib/python2.6/site-packages/suds/transport/http.py", line 67, in open\n    return self.u2open(u2request)\n', '  File "/usr/lib/python2.6/site-packages/suds/transport/http.py", line 132, in u2open\n    return url.open(u2request, timeout=tm)\n', '  File "/usr/lib64/python2.6/urllib2.py", line 391, in open\n    response = self._open(req, data)\n', '  File "/usr/lib64/python2.6/urllib2.py", line 409, in _open\n    \'_open\', req)\n', '  File "/usr/lib64/python2.6/urllib2.py", line 369, in _call_chain\n    result = func(*args)\n', '  File "/usr/lib64/python2.6/urllib2.py", line 1190, in http_open\n    return self.do_open(httplib.HTTPConnection, req)\n', '  File "/usr/lib64/python2.6/urllib2.py", line 1165, in do_open\n    raise URLError(err)\n']
None
2017-01-26 10:07:02,216 PI_DB SCRIPT INITIALIZING...
2017-01-26 10:08:05,252 Uncaught exception: <urlopen error [Errno 110] Connection timed out>
None
2017-01-26 10:08:05,253 Error type: <class 'urllib2.URLError'>
None
2017-01-26 10:08:05,257 Traceback: ['  File "/home/uwslowcontrol/pi_db/pi_db.py", line 269, in <module>\n    timeseries_client = Client(timeseries_url)\n', '  File "/usr/lib/python2.6/site-packages/suds/client.py", line 115, in __init__\n    self.wsdl = reader.open(url)\n', '  File "/usr/lib/python2.6/site-packages/suds/reader.py", line 150, in open\n    d = self.fn(url, self.options)\n', '  File "/usr/lib/python2.6/site-packages/suds/wsdl.py", line 136, in __init__\n    d = reader.open(url)\n', '  File "/usr/lib/python2.6/site-packages/suds/reader.py", line 74, in open\n    d = self.download(url)\n', '  File "/usr/lib/python2.6/site-packages/suds/reader.py", line 92, in download\n    fp = self.options.transport.open(Request(url))\n', '  File "/usr/lib/python2.6/site-packages/suds/transport/https.py", line 62, in open\n    return HttpTransport.open(self, request)\n', '  File "/usr/lib/python2.6/site-packages/suds/transport/http.py", line 67, in open\n    return self.u2open(u2request)\n', '  File "/usr/lib/python2.6/site-packages/suds/transport/http.py", line 132, in u2open\n    return url.open(u2request, timeout=tm)\n', '  File "/usr/lib64/python2.6/urllib2.py", line 391, in open\n    response = self._open(req, data)\n', '  File "/usr/lib64/python2.6/urllib2.py", line 409, in _open\n    \'_open\', req)\n', '  File "/usr/lib64/python2.6/urllib2.py", line 369, in _call_chain\n    result = func(*args)\n', '  File "/usr/lib64/python2.6/urllib2.py", line 1190, in http_open\n    return self.do_open(httplib.HTTPConnection, req)\n', '  File "/usr/lib64/python2.6/urllib2.py", line 1165, in do_open\n    raise URLError(err)\n']
None
2017-01-26 10:09:01,535 PI_DB SCRIPT INITIALIZING...
2017-01-26 10:10:04,568 Uncaught exception: <urlopen error [Errno 110] Connection timed out>
None
2017-01-26 10:10:04,569 Error type: <class 'urllib2.URLError'>
None
2017-01-26 10:10:04,572 Traceback: ['  File "/home/uwslowcontrol/pi_db/pi_db.py", line 269, in <module>\n    timeseries_client = Client(timeseries_url)\n', '  File "/usr/lib/python2.6/site-packages/suds/client.py", line 115, in __init__\n    self.wsdl = reader.open(url)\n', '  File "/usr/lib/python2.6/site-packages/suds/reader.py", line 150, in open\n    d = self.fn(url, self.options)\n', '  File "/usr/lib/python2.6/site-packages/suds/wsdl.py", line 136, in __init__\n    d = reader.open(url)\n', '  File "/usr/lib/python2.6/site-packages/suds/reader.py", line 74, in open\n    d = self.download(url)\n', '  File "/usr/lib/python2.6/site-packages/suds/reader.py", line 92, in download\n    fp = self.options.transport.open(Request(url))\n', '  File "/usr/lib/python2.6/site-packages/suds/transport/https.py", line 62, in open\n    return HttpTransport.open(self, request)\n', '  File "/usr/lib/python2.6/site-packages/suds/transport/http.py", line 67, in open\n    return self.u2open(u2request)\n', '  File "/usr/lib/python2.6/site-packages/suds/transport/http.py", line 132, in u2open\n    return url.open(u2request, timeout=tm)\n', '  File "/usr/lib64/python2.6/urllib2.py", line 391, in open\n    response = self._open(req, data)\n', '  File "/usr/lib64/python2.6/urllib2.py", line 409, in _open\n    \'_open\', req)\n', '  File "/usr/lib64/python2.6/urllib2.py", line 369, in _call_chain\n    result = func(*args)\n', '  File "/usr/lib64/python2.6/urllib2.py", line 1190, in http_open\n    return self.do_open(httplib.HTTPConnection, req)\n', '  File "/usr/lib64/python2.6/urllib2.py", line 1165, in do_open\n    raise URLError(err)\n']
None
2017-01-26 10:11:01,844 PI_DB SCRIPT INITIALIZING...
2017-01-26 10:12:04,881 Uncaught exception: <urlopen error [Errno 110] Connection timed out>
None
2017-01-26 10:12:04,882 Error type: <class 'urllib2.URLError'>
None
2017-01-26 10:12:04,884 Traceback: ['  File "/home/uwslowcontrol/pi_db/pi_db.py", line 269, in <module>\n    timeseries_client = Client(timeseries_url)\n', '  File "/usr/lib/python2.6/site-packages/suds/client.py", line 115, in __init__\n    self.wsdl = reader.open(url)\n', '  File "/usr/lib/python2.6/site-packages/suds/reader.py", line 150, in open\n    d = self.fn(url, self.options)\n', '  File "/usr/lib/python2.6/site-packages/suds/wsdl.py", line 136, in __init__\n    d = reader.open(url)\n', '  File "/usr/lib/python2.6/site-packages/suds/reader.py", line 74, in open\n    d = self.download(url)\n', '  File "/usr/lib/python2.6/site-packages/suds/reader.py", line 92, in download\n    fp = self.options.transport.open(Request(url))\n', '  File "/usr/lib/python2.6/site-packages/suds/transport/https.py", line 62, in open\n    return HttpTransport.open(self, request)\n', '  File "/usr/lib/python2.6/site-packages/suds/transport/http.py", line 67, in open\n    return self.u2open(u2request)\n', '  File "/usr/lib/python2.6/site-packages/suds/transport/http.py", line 132, in u2open\n    return url.open(u2request, timeout=tm)\n', '  File "/usr/lib64/python2.6/urllib2.py", line 391, in open\n    response = self._open(req, data)\n', '  File "/usr/lib64/python2.6/urllib2.py", line 409, in _open\n    \'_open\', req)\n', '  File "/usr/lib64/python2.6/urllib2.py", line 369, in _call_chain\n    result = func(*args)\n', '  File "/usr/lib64/python2.6/urllib2.py", line 1190, in http_open\n    return self.do_open(httplib.HTTPConnection, req)\n', '  File "/usr/lib64/python2.6/urllib2.py", line 1165, in do_open\n    raise URLError(err)\n']
None
2017-01-26 10:13:02,182 PI_DB SCRIPT INITIALIZING...
2017-01-26 10:14:05,219 Uncaught exception: <urlopen error [Errno 110] Connection timed out>
None
2017-01-26 10:14:05,220 Error type: <class 'urllib2.URLError'>
None
2017-01-26 10:14:05,222 Traceback: ['  File "/home/uwslowcontrol/pi_db/pi_db.py", line 269, in <module>\n    timeseries_client = Client(timeseries_url)\n', '  File "/usr/lib/python2.6/site-packages/suds/client.py", line 115, in __init__\n    self.wsdl = reader.open(url)\n', '  File "/usr/lib/python2.6/site-packages/suds/reader.py", line 150, in open\n    d = self.fn(url, self.options)\n', '  File "/usr/lib/python2.6/site-packages/suds/wsdl.py", line 136, in __init__\n    d = reader.open(url)\n', '  File "/usr/lib/python2.6/site-packages/suds/reader.py", line 74, in open\n    d = self.download(url)\n', '  File "/usr/lib/python2.6/site-packages/suds/reader.py", line 92, in download\n    fp = self.options.transport.open(Request(url))\n', '  File "/usr/lib/python2.6/site-packages/suds/transport/https.py", line 62, in open\n    return HttpTransport.open(self, request)\n', '  File "/usr/lib/python2.6/site-packages/suds/transport/http.py", line 67, in open\n    return self.u2open(u2request)\n', '  File "/usr/lib/python2.6/site-packages/suds/transport/http.py", line 132, in u2open\n    return url.open(u2request, timeout=tm)\n', '  File "/usr/lib64/python2.6/urllib2.py", line 391, in open\n    response = self._open(req, data)\n', '  File "/usr/lib64/python2.6/urllib2.py", line 409, in _open\n    \'_open\', req)\n', '  File "/usr/lib64/python2.6/urllib2.py", line 369, in _call_chain\n    result = func(*args)\n', '  File "/usr/lib64/python2.6/urllib2.py", line 1190, in http_open\n    return self.do_open(httplib.HTTPConnection, req)\n', '  File "/usr/lib64/python2.6/urllib2.py", line 1165, in do_open\n    raise URLError(err)\n']
None
2017-01-26 10:15:01,499 PI_DB SCRIPT INITIALIZING...
2017-01-26 10:16:04,533 Uncaught exception: <urlopen error [Errno 110] Connection timed out>
None
2017-01-26 10:16:04,534 Error type: <class 'urllib2.URLError'>
None
2017-01-26 10:16:04,537 Traceback: ['  File "/home/uwslowcontrol/pi_db/pi_db.py", line 269, in <module>\n    timeseries_client = Client(timeseries_url)\n', '  File "/usr/lib/python2.6/site-packages/suds/client.py", line 115, in __init__\n    self.wsdl = reader.open(url)\n', '  File "/usr/lib/python2.6/site-packages/suds/reader.py", line 150, in open\n    d = self.fn(url, self.options)\n', '  File "/usr/lib/python2.6/site-packages/suds/wsdl.py", line 136, in __init__\n    d = reader.open(url)\n', '  File "/usr/lib/python2.6/site-packages/suds/reader.py", line 74, in open\n    d = self.download(url)\n', '  File "/usr/lib/python2.6/site-packages/suds/reader.py", line 92, in download\n    fp = self.options.transport.open(Request(url))\n', '  File "/usr/lib/python2.6/site-packages/suds/transport/https.py", line 62, in open\n    return HttpTransport.open(self, request)\n', '  File "/usr/lib/python2.6/site-packages/suds/transport/http.py", line 67, in open\n    return self.u2open(u2request)\n', '  File "/usr/lib/python2.6/site-packages/suds/transport/http.py", line 132, in u2open\n    return url.open(u2request, timeout=tm)\n', '  File "/usr/lib64/python2.6/urllib2.py", line 391, in open\n    response = self._open(req, data)\n', '  File "/usr/lib64/python2.6/urllib2.py", line 409, in _open\n    \'_open\', req)\n', '  File "/usr/lib64/python2.6/urllib2.py", line 369, in _call_chain\n    result = func(*args)\n', '  File "/usr/lib64/python2.6/urllib2.py", line 1190, in http_open\n    return self.do_open(httplib.HTTPConnection, req)\n', '  File "/usr/lib64/python2.6/urllib2.py", line 1165, in do_open\n    raise URLError(err)\n']
None
2017-01-26 10:17:01,813 PI_DB SCRIPT INITIALIZING...
2017-01-26 13:59:25,709 PI_DB SCRIPT INITIALIZING...
2017-01-26 13:59:54,321 Uncaught exception: 
None
2017-01-26 13:59:54,322 Error type: <type 'exceptions.KeyboardInterrupt'>
None
2017-01-26 13:59:54,325 Traceback: ['  File "pi_db_try.py", line 557, in <module>\n    rawdata = getValues(poll_time,endpoll_time,pi_list)\n', '  File "pi_db_try.py", line 308, in getValues\n    machine["data"].append(get_pi(start_time,end_time,machine_index,pi_address+address,channel_number))\n', '  File "pi_db_try.py", line 296, in get_pi\n    returned_arcdata = timeseries_client.service.GetPIArchiveData(requests)\n', '  File "/usr/lib/python2.6/site-packages/suds/client.py", line 521, in __call__\n    return client.invoke(args, kwargs)\n', '  File "/usr/lib/python2.6/site-packages/suds/client.py", line 581, in invoke\n    result = self.send(soapenv)\n', '  File "/usr/lib/python2.6/site-packages/suds/client.py", line 613, in send\n    reply = self.options.transport.send(request)\n', '  File "/usr/lib/python2.6/site-packages/suds/transport/https.py", line 66, in send\n    return HttpTransport.send(self, request)\n', '  File "/usr/lib/python2.6/site-packages/suds/transport/http.py", line 82, in send\n    fp = self.u2open(u2request)\n', '  File "/usr/lib/python2.6/site-packages/suds/transport/http.py", line 132, in u2open\n    return url.open(u2request, timeout=tm)\n', '  File "/usr/lib64/python2.6/urllib2.py", line 391, in open\n    response = self._open(req, data)\n', '  File "/usr/lib64/python2.6/urllib2.py", line 409, in _open\n    \'_open\', req)\n', '  File "/usr/lib64/python2.6/urllib2.py", line 369, in _call_chain\n    result = func(*args)\n', '  File "/usr/lib64/python2.6/urllib2.py", line 1190, in http_open\n    return self.do_open(httplib.HTTPConnection, req)\n', '  File "/usr/lib64/python2.6/urllib2.py", line 1163, in do_open\n    r = h.getresponse()\n', '  File "/usr/lib64/python2.6/httplib.py", line 1049, in getresponse\n    response.begin()\n', '  File "/usr/lib64/python2.6/httplib.py", line 433, in begin\n    version, status, reason = self._read_status()\n', '  File "/usr/lib64/python2.6/httplib.py", line 389, in _read_status\n    line = self.fp.readline(_MAXLINE + 1)\n', '  File "/usr/lib64/python2.6/socket.py", line 479, in readline\n    data = self._sock.recv(self._rbufsize)\n']
None
2017-01-26 14:00:55,234 PI_DB SCRIPT INITIALIZING...
2017-01-29 07:06:46,803 Uncaught exception: [Errno 110] Connection timed out
None
2017-01-29 07:06:46,804 Error type: <class 'socket.error'>
None
2017-01-29 07:06:46,805 Traceback: ['  File "/home/uwslowcontrol/pi_db/pi_db.py", line 560, in <module>\n    saveValues(pi_data)\n', '  File "/home/uwslowcontrol/pi_db/pi_db.py", line 349, in saveValues\n    dbData.save(element)\n', '  File "/usr/lib/python2.6/site-packages/couchdb/client.py", line 439, in save\n    _, _, data = func(body=doc, **options)\n', '  File "/usr/lib/python2.6/site-packages/couchdb/http.py", line 545, in post_json\n    **params)\n', '  File "/usr/lib/python2.6/site-packages/couchdb/http.py", line 564, in _request_json\n    headers=headers, **params)\n', '  File "/usr/lib/python2.6/site-packages/couchdb/http.py", line 560, in _request\n    credentials=self.credentials)\n', '  File "/usr/lib/python2.6/site-packages/couchdb/http.py", line 330, in request\n    resp = _try_request_with_retries(iter(self.retry_delays))\n', '  File "/usr/lib/python2.6/site-packages/couchdb/http.py", line 290, in _try_request_with_retries\n    raise e\n']
None
2017-01-29 07:07:01,748 PI_DB SCRIPT INITIALIZING...
2017-01-29 18:59:16,559 Uncaught exception: [Errno 110] Connection timed out
None
2017-01-29 18:59:16,560 Error type: <class 'socket.error'>
None
2017-01-29 18:59:16,562 Traceback: ['  File "/home/uwslowcontrol/pi_db/pi_db.py", line 561, in <module>\n    channeldb = getChannelParameters(channeldb_last)\n', '  File "/home/uwslowcontrol/pi_db/pi_db.py", line 358, in getChannelParameters\n    channeldb = queryresults.rows[0].value\n', '  File "/usr/lib/python2.6/site-packages/couchdb/client.py", line 1205, in rows\n    self._fetch()\n', '  File "/usr/lib/python2.6/site-packages/couchdb/client.py", line 1191, in _fetch\n    data = self.view._exec(self.options)\n', '  File "/usr/lib/python2.6/site-packages/couchdb/client.py", line 1057, in _exec\n    _, _, data = _call_viewlike(self.resource, options)\n', '  File "/usr/lib/python2.6/site-packages/couchdb/client.py", line 1116, in _call_viewlike\n    return resource.get_json(**_encode_view_options(options))\n', '  File "/usr/lib/python2.6/site-packages/couchdb/http.py", line 541, in get_json\n    return self._request_json(\'GET\', path, headers=headers, **params)\n', '  File "/usr/lib/python2.6/site-packages/couchdb/http.py", line 564, in _request_json\n    headers=headers, **params)\n', '  File "/usr/lib/python2.6/site-packages/couchdb/http.py", line 560, in _request\n    credentials=self.credentials)\n', '  File "/usr/lib/python2.6/site-packages/couchdb/http.py", line 330, in request\n    resp = _try_request_with_retries(iter(self.retry_delays))\n', '  File "/usr/lib/python2.6/site-packages/couchdb/http.py", line 290, in _try_request_with_retries\n    raise e\n']
None
2017-01-29 19:00:01,834 PI_DB SCRIPT INITIALIZING...
2017-02-01 18:39:23,791 Uncaught exception: [Errno 110] Connection timed out
None
2017-02-01 18:39:23,792 Error type: <class 'socket.error'>
None
2017-02-01 18:39:23,794 Traceback: ['  File "/home/uwslowcontrol/pi_db/pi_db.py", line 560, in <module>\n    saveValues(pi_data)\n', '  File "/home/uwslowcontrol/pi_db/pi_db.py", line 349, in saveValues\n    dbData.save(element)\n', '  File "/usr/lib/python2.6/site-packages/couchdb/client.py", line 439, in save\n    _, _, data = func(body=doc, **options)\n', '  File "/usr/lib/python2.6/site-packages/couchdb/http.py", line 545, in post_json\n    **params)\n', '  File "/usr/lib/python2.6/site-packages/couchdb/http.py", line 564, in _request_json\n    headers=headers, **params)\n', '  File "/usr/lib/python2.6/site-packages/couchdb/http.py", line 560, in _request\n    credentials=self.credentials)\n', '  File "/usr/lib/python2.6/site-packages/couchdb/http.py", line 330, in request\n    resp = _try_request_with_retries(iter(self.retry_delays))\n', '  File "/usr/lib/python2.6/site-packages/couchdb/http.py", line 290, in _try_request_with_retries\n    raise e\n']
None
2017-02-01 18:40:02,074 PI_DB SCRIPT INITIALIZING...
2017-02-02 11:46:53,481 Uncaught exception: [Errno 110] Connection timed out
None
2017-02-02 11:46:53,482 Error type: <class 'socket.error'>
None
2017-02-02 11:46:53,484 Traceback: ['  File "/home/uwslowcontrol/pi_db/pi_db.py", line 560, in <module>\n    saveValues(pi_data)\n', '  File "/home/uwslowcontrol/pi_db/pi_db.py", line 349, in saveValues\n    dbData.save(element)\n', '  File "/usr/lib/python2.6/site-packages/couchdb/client.py", line 439, in save\n    _, _, data = func(body=doc, **options)\n', '  File "/usr/lib/python2.6/site-packages/couchdb/http.py", line 545, in post_json\n    **params)\n', '  File "/usr/lib/python2.6/site-packages/couchdb/http.py", line 564, in _request_json\n    headers=headers, **params)\n', '  File "/usr/lib/python2.6/site-packages/couchdb/http.py", line 560, in _request\n    credentials=self.credentials)\n', '  File "/usr/lib/python2.6/site-packages/couchdb/http.py", line 330, in request\n    resp = _try_request_with_retries(iter(self.retry_delays))\n', '  File "/usr/lib/python2.6/site-packages/couchdb/http.py", line 290, in _try_request_with_retries\n    raise e\n']
None
2017-02-02 11:47:01,750 PI_DB SCRIPT INITIALIZING...
2017-02-02 13:45:59,600 Uncaught exception: [Errno 110] Connection timed out
None
2017-02-02 13:45:59,601 Error type: <class 'socket.error'>
None
2017-02-02 13:45:59,603 Traceback: ['  File "/home/uwslowcontrol/pi_db/pi_db.py", line 560, in <module>\n    saveValues(pi_data)\n', '  File "/home/uwslowcontrol/pi_db/pi_db.py", line 349, in saveValues\n    dbData.save(element)\n', '  File "/usr/lib/python2.6/site-packages/couchdb/client.py", line 439, in save\n    _, _, data = func(body=doc, **options)\n', '  File "/usr/lib/python2.6/site-packages/couchdb/http.py", line 545, in post_json\n    **params)\n', '  File "/usr/lib/python2.6/site-packages/couchdb/http.py", line 564, in _request_json\n    headers=headers, **params)\n', '  File "/usr/lib/python2.6/site-packages/couchdb/http.py", line 560, in _request\n    credentials=self.credentials)\n', '  File "/usr/lib/python2.6/site-packages/couchdb/http.py", line 330, in request\n    resp = _try_request_with_retries(iter(self.retry_delays))\n', '  File "/usr/lib/python2.6/site-packages/couchdb/http.py", line 290, in _try_request_with_retries\n    raise e\n']
None
2017-02-02 13:46:01,882 PI_DB SCRIPT INITIALIZING...
2017-02-05 15:53:19,232 Uncaught exception: [Errno 110] Connection timed out
None
2017-02-05 15:53:19,233 Error type: <class 'socket.error'>
None
2017-02-05 15:53:19,235 Traceback: ['  File "/home/uwslowcontrol/pi_db/pi_db.py", line 560, in <module>\n    saveValues(pi_data)\n', '  File "/home/uwslowcontrol/pi_db/pi_db.py", line 349, in saveValues\n    dbData.save(element)\n', '  File "/usr/lib/python2.6/site-packages/couchdb/client.py", line 439, in save\n    _, _, data = func(body=doc, **options)\n', '  File "/usr/lib/python2.6/site-packages/couchdb/http.py", line 545, in post_json\n    **params)\n', '  File "/usr/lib/python2.6/site-packages/couchdb/http.py", line 564, in _request_json\n    headers=headers, **params)\n', '  File "/usr/lib/python2.6/site-packages/couchdb/http.py", line 560, in _request\n    credentials=self.credentials)\n', '  File "/usr/lib/python2.6/site-packages/couchdb/http.py", line 330, in request\n    resp = _try_request_with_retries(iter(self.retry_delays))\n', '  File "/usr/lib/python2.6/site-packages/couchdb/http.py", line 290, in _try_request_with_retries\n    raise e\n']
None
2017-02-05 15:54:01,513 PI_DB SCRIPT INITIALIZING...
2017-02-06 04:29:09,645 Uncaught exception: [Errno 110] Connection timed out
None
2017-02-06 04:29:09,646 Error type: <class 'socket.error'>
None
2017-02-06 04:29:09,648 Traceback: ['  File "/home/uwslowcontrol/pi_db/pi_db.py", line 560, in <module>\n    saveValues(pi_data)\n', '  File "/home/uwslowcontrol/pi_db/pi_db.py", line 349, in saveValues\n    dbData.save(element)\n', '  File "/usr/lib/python2.6/site-packages/couchdb/client.py", line 439, in save\n    _, _, data = func(body=doc, **options)\n', '  File "/usr/lib/python2.6/site-packages/couchdb/http.py", line 545, in post_json\n    **params)\n', '  File "/usr/lib/python2.6/site-packages/couchdb/http.py", line 564, in _request_json\n    headers=headers, **params)\n', '  File "/usr/lib/python2.6/site-packages/couchdb/http.py", line 560, in _request\n    credentials=self.credentials)\n', '  File "/usr/lib/python2.6/site-packages/couchdb/http.py", line 330, in request\n    resp = _try_request_with_retries(iter(self.retry_delays))\n', '  File "/usr/lib/python2.6/site-packages/couchdb/http.py", line 290, in _try_request_with_retries\n    raise e\n']
None
2017-02-06 04:30:01,910 PI_DB SCRIPT INITIALIZING...
