017-01-23 20:17:07,997 Uncaught exception: getChannelParameters() takes exactly 1 argument (0 given)
None
2017-01-23 20:17:07,998 Error type: <type 'exceptions.TypeError'>
None
2017-01-23 20:17:07,998 Traceback: ['  File "/home/uwslowcontrol/pi_db/pi_db.py", line 551, in <module>\n    channeldb = getChannelParameters()\n']
None
2017-01-23 20:18:01,248 PI_DB SCRIPT INITIALIZING...
2017-01-23 20:18:07,514 Uncaught exception: getChannelParameters() takes exactly 1 argument (0 given)
None
2017-01-23 20:18:07,514 Error type: <type 'exceptions.TypeError'>
None
2017-01-23 20:18:07,515 Traceback: ['  File "/home/uwslowcontrol/pi_db/pi_db.py", line 551, in <module>\n    channeldb = getChannelParameters()\n']
None
2017-01-23 20:19:01,786 PI_DB SCRIPT INITIALIZING...
2017-01-23 20:19:07,981 Uncaught exception: getChannelParameters() takes exactly 1 argument (0 given)
None
2017-01-23 20:19:07,981 Error type: <type 'exceptions.TypeError'>
None
2017-01-23 20:19:07,981 Traceback: ['  File "/home/uwslowcontrol/pi_db/pi_db.py", line 551, in <module>\n    channeldb = getChannelParameters()\n']
None
2017-01-23 20:20:02,245 PI_DB SCRIPT INITIALIZING...
2017-01-23 20:20:08,554 Uncaught exception: getChannelParameters() takes exactly 1 argument (0 given)
None
2017-01-23 20:20:08,554 Error type: <type 'exceptions.TypeError'>
None
2017-01-23 20:20:08,554 Traceback: ['  File "/home/uwslowcontrol/pi_db/pi_db.py", line 551, in <module>\n    channeldb = getChannelParameters()\n']
None
2017-01-23 20:21:01,810 PI_DB SCRIPT INITIALIZING...
2017-01-23 20:21:07,990 Uncaught exception: getChannelParameters() takes exactly 1 argument (0 given)
None
2017-01-23 20:21:07,991 Error type: <type 'exceptions.TypeError'>
None
2017-01-23 20:21:07,991 Traceback: ['  File "/home/uwslowcontrol/pi_db/pi_db.py", line 551, in <module>\n    channeldb = getChannelParameters()\n']
None
2017-01-23 20:21:56,564 PI_DB SCRIPT INITIALIZING...
2017-01-23 20:22:15,272 Uncaught exception: 
None
2017-01-23 20:22:15,273 Error type: <type 'exceptions.KeyboardInterrupt'>
None
2017-01-23 20:22:15,273 Traceback: ['  File "pi_db.py", line 564, in <module>\n    time.sleep(wait_time)\n']
None
2017-01-23 20:22:22,200 PI_DB SCRIPT INITIALIZING...
2017-01-26 10:04:47,138 Uncaught exception: <urlopen error [Errno 110] Connection timed out>
None
2017-01-26 10:04:47,139 Error type: <class 'urllib2.URLError'>
None
2017-01-26 10:04:47,141 Traceback: ['  File "/home/uwslowcontrol/pi_db/pi_db.py", line 551, in <module>\n    rawdata = getValues(poll_time,endpoll_time,pi_list)\n', '  File "/home/uwslowcontrol/pi_db/pi_db.py", line 302, in getValues\n    machine["data"].append(get_pi(start_time,end_time,machine_index,pi_address+address,channel_number))\n', '  File "/home/uwslowcontrol/pi_db/pi_db.py", line 290, in get_pi\n    returned_arcdata = timeseries_client.service.GetPIArchiveData(requests)\n', '  File "/usr/lib/python2.6/site-packages/suds/client.py", line 521, in __call__\n    return client.invoke(args, kwargs)\n', '  File "/usr/lib/python2.6/site-packages/suds/client.py", line 581, in invoke\n    result = self.send(soapenv)\n', '  File "/usr/lib/python2.6/site-packages/suds/client.py", line 613, in send\n    reply = self.options.transport.send(request)\n', '  File "/usr/lib/python2.6/site-packages/suds/transport/https.py", line 66, in send\n    return HttpTransport.send(self, request)\n', '  File "/usr/lib/python2.6/site-packages/suds/transport/http.py", line 82, in send\n    fp = self.u2open(u2request)\n', '  File "/usr/lib/python2.6/site-packages/suds/transport/http.py", line 132, in u2open\n    return url.open(u2request, timeout=tm)\n', '  File "/usr/lib64/python2.6/urllib2.py", line 391, in open\n    response = self._open(req, data)\n', '  File "/usr/lib64/python2.6/urllib2.py", line 409, in _open\n    \'_open\', req)\n', '  File "/usr/lib64/python2.6/urllib2.py", line 369, in _call_chain\n    result = func(*args)\n', '  File "/usr/lib64/python2.6/urllib2.py", line 1190, in http_open\n    return self.do_open(httplib.HTTPConnection, req)\n', '  File "/usr/lib64/python2.6/urllib2.py", line 1165, in do_open\n    raise URLError(err)\n']
None
2017-01-26 10:05:01,878 PI_DB SCRIPT INITIALIZING...
2017-01-26 10:06:04,916 Uncaught exception: <urlopen error [Errno 110] Connection timed out>
None
2017-01-26 10:06:04,916 Error type: <class 'urllib2.URLError'>
None
2017-01-26 10:06:04,919 Traceback: ['  File "/home/uwslowcontrol/pi_db/pi_db.py", line 269, in <module>\n    timeseries_client = Client(timeseries_url)\n', '  File "/usr/lib/python2.6/site-packages/suds/client.py", line 115, in __init__\n    self.wsdl = reader.open(url)\n', '  File "/usr/lib/python2.6/site-packages/suds/reader.py", line 150, in open\n    d = self.fn(url, self.options)\n', '  File "/usr/lib/python2.6/site-packages/suds/wsdl.py", line 136, in __init__\n    d = reader.open(url)\n', '  File "/usr/lib/python2.6/site-packages/suds/reader.py", line 74, in open\n    d = self.download(url)\n', '  File "/usr/lib/python2.6/site-packages/suds/reader.py", line 92, in download\n    fp = self.options.transport.open(Request(url))\n', '  File "/usr/lib/python2.6/site-packages/suds/transport/https.py", line 62, in open\n    return HttpTransport.open(self, request)\n', '  File "/usr/lib/python2.6/site-packages/suds/transport/http.py", line 67, in open\n    return self.u2open(u2request)\n', '  File "/usr/lib/python2.6/site-packages/suds/transport/http.py", line 132, in u2open\n    return url.open(u2request, timeout=tm)\n', '  File "/usr/lib64/python2.6/urllib2.py", line 391, in open\n    response = self._open(req, data)\n', '  File "/usr/lib64/python2.6/urllib2.py", line 409, in _open\n    \'_open\', req)\n', '  File "/usr/lib64/python2.6/urllib2.py", line 369, in _call_chain\n    result = func(*args)\n', '  File "/usr/lib64/python2.6/urllib2.py", line 1190, in http_open\n    return self.do_open(httplib.HTTPConnection, req)\n', '  File "/usr/lib64/python2.6/urllib2.py", line 1165, in do_open\n    raise URLError(err)\n']
None
2017-01-26 10:07:02,216 PI_DB SCRIPT INITIALIZING...
2017-01-26 10:08:05,252 Uncaught exception: <urlopen error [Errno 110] Connection timed out>
None
2017-01-26 10:08:05,253 Error type: <class 'urllib2.URLError'>
None
2017-01-26 10:08:05,257 Traceback: ['  File "/home/uwslowcontrol/pi_db/pi_db.py", line 269, in <module>\n    timeseries_client = Client(timeseries_url)\n', '  File "/usr/lib/python2.6/site-packages/suds/client.py", line 115, in __init__\n    self.wsdl = reader.open(url)\n', '  File "/usr/lib/python2.6/site-packages/suds/reader.py", line 150, in open\n    d = self.fn(url, self.options)\n', '  File "/usr/lib/python2.6/site-packages/suds/wsdl.py", line 136, in __init__\n    d = reader.open(url)\n', '  File "/usr/lib/python2.6/site-packages/suds/reader.py", line 74, in open\n    d = self.download(url)\n', '  File "/usr/lib/python2.6/site-packages/suds/reader.py", line 92, in download\n    fp = self.options.transport.open(Request(url))\n', '  File "/usr/lib/python2.6/site-packages/suds/transport/https.py", line 62, in open\n    return HttpTransport.open(self, request)\n', '  File "/usr/lib/python2.6/site-packages/suds/transport/http.py", line 67, in open\n    return self.u2open(u2request)\n', '  File "/usr/lib/python2.6/site-packages/suds/transport/http.py", line 132, in u2open\n    return url.open(u2request, timeout=tm)\n', '  File "/usr/lib64/python2.6/urllib2.py", line 391, in open\n    response = self._open(req, data)\n', '  File "/usr/lib64/python2.6/urllib2.py", line 409, in _open\n    \'_open\', req)\n', '  File "/usr/lib64/python2.6/urllib2.py", line 369, in _call_chain\n    result = func(*args)\n', '  File "/usr/lib64/python2.6/urllib2.py", line 1190, in http_open\n    return self.do_open(httplib.HTTPConnection, req)\n', '  File "/usr/lib64/python2.6/urllib2.py", line 1165, in do_open\n    raise URLError(err)\n']
None
2017-01-26 10:09:01,535 PI_DB SCRIPT INITIALIZING...
2017-01-26 10:10:04,568 Uncaught exception: <urlopen error [Errno 110] Connection timed out>
None
2017-01-26 10:10:04,569 Error type: <class 'urllib2.URLError'>
None
2017-01-26 10:10:04,572 Traceback: ['  File "/home/uwslowcontrol/pi_db/pi_db.py", line 269, in <module>\n    timeseries_client = Client(timeseries_url)\n', '  File "/usr/lib/python2.6/site-packages/suds/client.py", line 115, in __init__\n    self.wsdl = reader.open(url)\n', '  File "/usr/lib/python2.6/site-packages/suds/reader.py", line 150, in open\n    d = self.fn(url, self.options)\n', '  File "/usr/lib/python2.6/site-packages/suds/wsdl.py", line 136, in __init__\n    d = reader.open(url)\n', '  File "/usr/lib/python2.6/site-packages/suds/reader.py", line 74, in open\n    d = self.download(url)\n', '  File "/usr/lib/python2.6/site-packages/suds/reader.py", line 92, in download\n    fp = self.options.transport.open(Request(url))\n', '  File "/usr/lib/python2.6/site-packages/suds/transport/https.py", line 62, in open\n    return HttpTransport.open(self, request)\n', '  File "/usr/lib/python2.6/site-packages/suds/transport/http.py", line 67, in open\n    return self.u2open(u2request)\n', '  File "/usr/lib/python2.6/site-packages/suds/transport/http.py", line 132, in u2open\n    return url.open(u2request, timeout=tm)\n', '  File "/usr/lib64/python2.6/urllib2.py", line 391, in open\n    response = self._open(req, data)\n', '  File "/usr/lib64/python2.6/urllib2.py", line 409, in _open\n    \'_open\', req)\n', '  File "/usr/lib64/python2.6/urllib2.py", line 369, in _call_chain\n    result = func(*args)\n', '  File "/usr/lib64/python2.6/urllib2.py", line 1190, in http_open\n    return self.do_open(httplib.HTTPConnection, req)\n', '  File "/usr/lib64/python2.6/urllib2.py", line 1165, in do_open\n    raise URLError(err)\n']
None
2017-01-26 10:11:01,844 PI_DB SCRIPT INITIALIZING...
2017-01-26 10:12:04,881 Uncaught exception: <urlopen error [Errno 110] Connection timed out>
None
2017-01-26 10:12:04,882 Error type: <class 'urllib2.URLError'>
None
2017-01-26 10:12:04,884 Traceback: ['  File "/home/uwslowcontrol/pi_db/pi_db.py", line 269, in <module>\n    timeseries_client = Client(timeseries_url)\n', '  File "/usr/lib/python2.6/site-packages/suds/client.py", line 115, in __init__\n    self.wsdl = reader.open(url)\n', '  File "/usr/lib/python2.6/site-packages/suds/reader.py", line 150, in open\n    d = self.fn(url, self.options)\n', '  File "/usr/lib/python2.6/site-packages/suds/wsdl.py", line 136, in __init__\n    d = reader.open(url)\n', '  File "/usr/lib/python2.6/site-packages/suds/reader.py", line 74, in open\n    d = self.download(url)\n', '  File "/usr/lib/python2.6/site-packages/suds/reader.py", line 92, in download\n    fp = self.options.transport.open(Request(url))\n', '  File "/usr/lib/python2.6/site-packages/suds/transport/https.py", line 62, in open\n    return HttpTransport.open(self, request)\n', '  File "/usr/lib/python2.6/site-packages/suds/transport/http.py", line 67, in open\n    return self.u2open(u2request)\n', '  File "/usr/lib/python2.6/site-packages/suds/transport/http.py", line 132, in u2open\n    return url.open(u2request, timeout=tm)\n', '  File "/usr/lib64/python2.6/urllib2.py", line 391, in open\n    response = self._open(req, data)\n', '  File "/usr/lib64/python2.6/urllib2.py", line 409, in _open\n    \'_open\', req)\n', '  File "/usr/lib64/python2.6/urllib2.py", line 369, in _call_chain\n    result = func(*args)\n', '  File "/usr/lib64/python2.6/urllib2.py", line 1190, in http_open\n    return self.do_open(httplib.HTTPConnection, req)\n', '  File "/usr/lib64/python2.6/urllib2.py", line 1165, in do_open\n    raise URLError(err)\n']
None
2017-01-26 10:13:02,182 PI_DB SCRIPT INITIALIZING...
2017-01-26 10:14:05,219 Uncaught exception: <urlopen error [Errno 110] Connection timed out>
None
2017-01-26 10:14:05,220 Error type: <class 'urllib2.URLError'>
None
2017-01-26 10:14:05,222 Traceback: ['  File "/home/uwslowcontrol/pi_db/pi_db.py", line 269, in <module>\n    timeseries_client = Client(timeseries_url)\n', '  File "/usr/lib/python2.6/site-packages/suds/client.py", line 115, in __init__\n    self.wsdl = reader.open(url)\n', '  File "/usr/lib/python2.6/site-packages/suds/reader.py", line 150, in open\n    d = self.fn(url, self.options)\n', '  File "/usr/lib/python2.6/site-packages/suds/wsdl.py", line 136, in __init__\n    d = reader.open(url)\n', '  File "/usr/lib/python2.6/site-packages/suds/reader.py", line 74, in open\n    d = self.download(url)\n', '  File "/usr/lib/python2.6/site-packages/suds/reader.py", line 92, in download\n    fp = self.options.transport.open(Request(url))\n', '  File "/usr/lib/python2.6/site-packages/suds/transport/https.py", line 62, in open\n    return HttpTransport.open(self, request)\n', '  File "/usr/lib/python2.6/site-packages/suds/transport/http.py", line 67, in open\n    return self.u2open(u2request)\n', '  File "/usr/lib/python2.6/site-packages/suds/transport/http.py", line 132, in u2open\n    return url.open(u2request, timeout=tm)\n', '  File "/usr/lib64/python2.6/urllib2.py", line 391, in open\n    response = self._open(req, data)\n', '  File "/usr/lib64/python2.6/urllib2.py", line 409, in _open\n    \'_open\', req)\n', '  File "/usr/lib64/python2.6/urllib2.py", line 369, in _call_chain\n    result = func(*args)\n', '  File "/usr/lib64/python2.6/urllib2.py", line 1190, in http_open\n    return self.do_open(httplib.HTTPConnection, req)\n', '  File "/usr/lib64/python2.6/urllib2.py", line 1165, in do_open\n    raise URLError(err)\n']
None
2017-01-26 10:15:01,499 PI_DB SCRIPT INITIALIZING...
2017-01-26 10:16:04,533 Uncaught exception: <urlopen error [Errno 110] Connection timed out>
None
2017-01-26 10:16:04,534 Error type: <class 'urllib2.URLError'>
None
2017-01-26 10:16:04,537 Traceback: ['  File "/home/uwslowcontrol/pi_db/pi_db.py", line 269, in <module>\n    timeseries_client = Client(timeseries_url)\n', '  File "/usr/lib/python2.6/site-packages/suds/client.py", line 115, in __init__\n    self.wsdl = reader.open(url)\n', '  File "/usr/lib/python2.6/site-packages/suds/reader.py", line 150, in open\n    d = self.fn(url, self.options)\n', '  File "/usr/lib/python2.6/site-packages/suds/wsdl.py", line 136, in __init__\n    d = reader.open(url)\n', '  File "/usr/lib/python2.6/site-packages/suds/reader.py", line 74, in open\n    d = self.download(url)\n', '  File "/usr/lib/python2.6/site-packages/suds/reader.py", line 92, in download\n    fp = self.options.transport.open(Request(url))\n', '  File "/usr/lib/python2.6/site-packages/suds/transport/https.py", line 62, in open\n    return HttpTransport.open(self, request)\n', '  File "/usr/lib/python2.6/site-packages/suds/transport/http.py", line 67, in open\n    return self.u2open(u2request)\n', '  File "/usr/lib/python2.6/site-packages/suds/transport/http.py", line 132, in u2open\n    return url.open(u2request, timeout=tm)\n', '  File "/usr/lib64/python2.6/urllib2.py", line 391, in open\n    response = self._open(req, data)\n', '  File "/usr/lib64/python2.6/urllib2.py", line 409, in _open\n    \'_open\', req)\n', '  File "/usr/lib64/python2.6/urllib2.py", line 369, in _call_chain\n    result = func(*args)\n', '  File "/usr/lib64/python2.6/urllib2.py", line 1190, in http_open\n    return self.do_open(httplib.HTTPConnection, req)\n', '  File "/usr/lib64/python2.6/urllib2.py", line 1165, in do_open\n    raise URLError(err)\n']
None
2017-01-26 10:17:01,813 PI_DB SCRIPT INITIALIZING...
2017-01-26 13:59:25,709 PI_DB SCRIPT INITIALIZING...
2017-01-26 13:59:54,321 Uncaught exception: 
None
2017-01-26 13:59:54,322 Error type: <type 'exceptions.KeyboardInterrupt'>
None
2017-01-26 13:59:54,325 Traceback: ['  File "pi_db_try.py", line 557, in <module>\n    rawdata = getValues(poll_time,endpoll_time,pi_list)\n', '  File "pi_db_try.py", line 308, in getValues\n    machine["data"].append(get_pi(start_time,end_time,machine_index,pi_address+address,channel_number))\n', '  File "pi_db_try.py", line 296, in get_pi\n    returned_arcdata = timeseries_client.service.GetPIArchiveData(requests)\n', '  File "/usr/lib/python2.6/site-packages/suds/client.py", line 521, in __call__\n    return client.invoke(args, kwargs)\n', '  File "/usr/lib/python2.6/site-packages/suds/client.py", line 581, in invoke\n    result = self.send(soapenv)\n', '  File "/usr/lib/python2.6/site-packages/suds/client.py", line 613, in send\n    reply = self.options.transport.send(request)\n', '  File "/usr/lib/python2.6/site-packages/suds/transport/https.py", line 66, in send\n    return HttpTransport.send(self, request)\n', '  File "/usr/lib/python2.6/site-packages/suds/transport/http.py", line 82, in send\n    fp = self.u2open(u2request)\n', '  File "/usr/lib/python2.6/site-packages/suds/transport/http.py", line 132, in u2open\n    return url.open(u2request, timeout=tm)\n', '  File "/usr/lib64/python2.6/urllib2.py", line 391, in open\n    response = self._open(req, data)\n', '  File "/usr/lib64/python2.6/urllib2.py", line 409, in _open\n    \'_open\', req)\n', '  File "/usr/lib64/python2.6/urllib2.py", line 369, in _call_chain\n    result = func(*args)\n', '  File "/usr/lib64/python2.6/urllib2.py", line 1190, in http_open\n    return self.do_open(httplib.HTTPConnection, req)\n', '  File "/usr/lib64/python2.6/urllib2.py", line 1163, in do_open\n    r = h.getresponse()\n', '  File "/usr/lib64/python2.6/httplib.py", line 1049, in getresponse\n    response.begin()\n', '  File "/usr/lib64/python2.6/httplib.py", line 433, in begin\n    version, status, reason = self._read_status()\n', '  File "/usr/lib64/python2.6/httplib.py", line 389, in _read_status\n    line = self.fp.readline(_MAXLINE + 1)\n', '  File "/usr/lib64/python2.6/socket.py", line 479, in readline\n    data = self._sock.recv(self._rbufsize)\n']
None
2017-01-26 14:00:55,234 PI_DB SCRIPT INITIALIZING...
2017-01-29 07:06:46,803 Uncaught exception: [Errno 110] Connection timed out
None
2017-01-29 07:06:46,804 Error type: <class 'socket.error'>
None
2017-01-29 07:06:46,805 Traceback: ['  File "/home/uwslowcontrol/pi_db/pi_db.py", line 560, in <module>\n    saveValues(pi_data)\n', '  File "/home/uwslowcontrol/pi_db/pi_db.py", line 349, in saveValues\n    dbData.save(element)\n', '  File "/usr/lib/python2.6/site-packages/couchdb/client.py", line 439, in save\n    _, _, data = func(body=doc, **options)\n', '  File "/usr/lib/python2.6/site-packages/couchdb/http.py", line 545, in post_json\n    **params)\n', '  File "/usr/lib/python2.6/site-packages/couchdb/http.py", line 564, in _request_json\n    headers=headers, **params)\n', '  File "/usr/lib/python2.6/site-packages/couchdb/http.py", line 560, in _request\n    credentials=self.credentials)\n', '  File "/usr/lib/python2.6/site-packages/couchdb/http.py", line 330, in request\n    resp = _try_request_with_retries(iter(self.retry_delays))\n', '  File "/usr/lib/python2.6/site-packages/couchdb/http.py", line 290, in _try_request_with_retries\n    raise e\n']
None
2017-01-29 07:07:01,748 PI_DB SCRIPT INITIALIZING...
2017-01-29 18:59:16,559 Uncaught exception: [Errno 110] Connection timed out
None
2017-01-29 18:59:16,560 Error type: <class 'socket.error'>
None
2017-01-29 18:59:16,562 Traceback: ['  File "/home/uwslowcontrol/pi_db/pi_db.py", line 561, in <module>\n    channeldb = getChannelParameters(channeldb_last)\n', '  File "/home/uwslowcontrol/pi_db/pi_db.py", line 358, in getChannelParameters\n    channeldb = queryresults.rows[0].value\n', '  File "/usr/lib/python2.6/site-packages/couchdb/client.py", line 1205, in rows\n    self._fetch()\n', '  File "/usr/lib/python2.6/site-packages/couchdb/client.py", line 1191, in _fetch\n    data = self.view._exec(self.options)\n', '  File "/usr/lib/python2.6/site-packages/couchdb/client.py", line 1057, in _exec\n    _, _, data = _call_viewlike(self.resource, options)\n', '  File "/usr/lib/python2.6/site-packages/couchdb/client.py", line 1116, in _call_viewlike\n    return resource.get_json(**_encode_view_options(options))\n', '  File "/usr/lib/python2.6/site-packages/couchdb/http.py", line 541, in get_json\n    return self._request_json(\'GET\', path, headers=headers, **params)\n', '  File "/usr/lib/python2.6/site-packages/couchdb/http.py", line 564, in _request_json\n    headers=headers, **params)\n', '  File "/usr/lib/python2.6/site-packages/couchdb/http.py", line 560, in _request\n    credentials=self.credentials)\n', '  File "/usr/lib/python2.6/site-packages/couchdb/http.py", line 330, in request\n    resp = _try_request_with_retries(iter(self.retry_delays))\n', '  File "/usr/lib/python2.6/site-packages/couchdb/http.py", line 290, in _try_request_with_retries\n    raise e\n']
None
2017-01-29 19:00:01,834 PI_DB SCRIPT INITIALIZING...
2017-02-01 18:39:23,791 Uncaught exception: [Errno 110] Connection timed out
None
2017-02-01 18:39:23,792 Error type: <class 'socket.error'>
None
2017-02-01 18:39:23,794 Traceback: ['  File "/home/uwslowcontrol/pi_db/pi_db.py", line 560, in <module>\n    saveValues(pi_data)\n', '  File "/home/uwslowcontrol/pi_db/pi_db.py", line 349, in saveValues\n    dbData.save(element)\n', '  File "/usr/lib/python2.6/site-packages/couchdb/client.py", line 439, in save\n    _, _, data = func(body=doc, **options)\n', '  File "/usr/lib/python2.6/site-packages/couchdb/http.py", line 545, in post_json\n    **params)\n', '  File "/usr/lib/python2.6/site-packages/couchdb/http.py", line 564, in _request_json\n    headers=headers, **params)\n', '  File "/usr/lib/python2.6/site-packages/couchdb/http.py", line 560, in _request\n    credentials=self.credentials)\n', '  File "/usr/lib/python2.6/site-packages/couchdb/http.py", line 330, in request\n    resp = _try_request_with_retries(iter(self.retry_delays))\n', '  File "/usr/lib/python2.6/site-packages/couchdb/http.py", line 290, in _try_request_with_retries\n    raise e\n']
None
2017-02-01 18:40:02,074 PI_DB SCRIPT INITIALIZING...
2017-02-02 11:46:53,481 Uncaught exception: [Errno 110] Connection timed out
None
2017-02-02 11:46:53,482 Error type: <class 'socket.error'>
None
2017-02-02 11:46:53,484 Traceback: ['  File "/home/uwslowcontrol/pi_db/pi_db.py", line 560, in <module>\n    saveValues(pi_data)\n', '  File "/home/uwslowcontrol/pi_db/pi_db.py", line 349, in saveValues\n    dbData.save(element)\n', '  File "/usr/lib/python2.6/site-packages/couchdb/client.py", line 439, in save\n    _, _, data = func(body=doc, **options)\n', '  File "/usr/lib/python2.6/site-packages/couchdb/http.py", line 545, in post_json\n    **params)\n', '  File "/usr/lib/python2.6/site-packages/couchdb/http.py", line 564, in _request_json\n    headers=headers, **params)\n', '  File "/usr/lib/python2.6/site-packages/couchdb/http.py", line 560, in _request\n    credentials=self.credentials)\n', '  File "/usr/lib/python2.6/site-packages/couchdb/http.py", line 330, in request\n    resp = _try_request_with_retries(iter(self.retry_delays))\n', '  File "/usr/lib/python2.6/site-packages/couchdb/http.py", line 290, in _try_request_with_retries\n    raise e\n']
None
2017-02-02 11:47:01,750 PI_DB SCRIPT INITIALIZING...
2017-02-02 13:45:59,600 Uncaught exception: [Errno 110] Connection timed out
None
2017-02-02 13:45:59,601 Error type: <class 'socket.error'>
None
2017-02-02 13:45:59,603 Traceback: ['  File "/home/uwslowcontrol/pi_db/pi_db.py", line 560, in <module>\n    saveValues(pi_data)\n', '  File "/home/uwslowcontrol/pi_db/pi_db.py", line 349, in saveValues\n    dbData.save(element)\n', '  File "/usr/lib/python2.6/site-packages/couchdb/client.py", line 439, in save\n    _, _, data = func(body=doc, **options)\n', '  File "/usr/lib/python2.6/site-packages/couchdb/http.py", line 545, in post_json\n    **params)\n', '  File "/usr/lib/python2.6/site-packages/couchdb/http.py", line 564, in _request_json\n    headers=headers, **params)\n', '  File "/usr/lib/python2.6/site-packages/couchdb/http.py", line 560, in _request\n    credentials=self.credentials)\n', '  File "/usr/lib/python2.6/site-packages/couchdb/http.py", line 330, in request\n    resp = _try_request_with_retries(iter(self.retry_delays))\n', '  File "/usr/lib/python2.6/site-packages/couchdb/http.py", line 290, in _try_request_with_retries\n    raise e\n']
None
2017-02-02 13:46:01,882 PI_DB SCRIPT INITIALIZING...
2017-02-05 15:53:19,232 Uncaught exception: [Errno 110] Connection timed out
None
2017-02-05 15:53:19,233 Error type: <class 'socket.error'>
None
2017-02-05 15:53:19,235 Traceback: ['  File "/home/uwslowcontrol/pi_db/pi_db.py", line 560, in <module>\n    saveValues(pi_data)\n', '  File "/home/uwslowcontrol/pi_db/pi_db.py", line 349, in saveValues\n    dbData.save(element)\n', '  File "/usr/lib/python2.6/site-packages/couchdb/client.py", line 439, in save\n    _, _, data = func(body=doc, **options)\n', '  File "/usr/lib/python2.6/site-packages/couchdb/http.py", line 545, in post_json\n    **params)\n', '  File "/usr/lib/python2.6/site-packages/couchdb/http.py", line 564, in _request_json\n    headers=headers, **params)\n', '  File "/usr/lib/python2.6/site-packages/couchdb/http.py", line 560, in _request\n    credentials=self.credentials)\n', '  File "/usr/lib/python2.6/site-packages/couchdb/http.py", line 330, in request\n    resp = _try_request_with_retries(iter(self.retry_delays))\n', '  File "/usr/lib/python2.6/site-packages/couchdb/http.py", line 290, in _try_request_with_retries\n    raise e\n']
None
2017-02-05 15:54:01,513 PI_DB SCRIPT INITIALIZING...
2017-02-06 04:29:09,645 Uncaught exception: [Errno 110] Connection timed out
None
2017-02-06 04:29:09,646 Error type: <class 'socket.error'>
None
2017-02-06 04:29:09,648 Traceback: ['  File "/home/uwslowcontrol/pi_db/pi_db.py", line 560, in <module>\n    saveValues(pi_data)\n', '  File "/home/uwslowcontrol/pi_db/pi_db.py", line 349, in saveValues\n    dbData.save(element)\n', '  File "/usr/lib/python2.6/site-packages/couchdb/client.py", line 439, in save\n    _, _, data = func(body=doc, **options)\n', '  File "/usr/lib/python2.6/site-packages/couchdb/http.py", line 545, in post_json\n    **params)\n', '  File "/usr/lib/python2.6/site-packages/couchdb/http.py", line 564, in _request_json\n    headers=headers, **params)\n', '  File "/usr/lib/python2.6/site-packages/couchdb/http.py", line 560, in _request\n    credentials=self.credentials)\n', '  File "/usr/lib/python2.6/site-packages/couchdb/http.py", line 330, in request\n    resp = _try_request_with_retries(iter(self.retry_delays))\n', '  File "/usr/lib/python2.6/site-packages/couchdb/http.py", line 290, in _try_request_with_retries\n    raise e\n']
None
2017-02-06 04:30:01,910 PI_DB SCRIPT INITIALIZING...
2017-02-16 00:21:18,138 Uncaught exception: [Errno 110] Connection timed out
None
2017-02-16 00:21:18,139 Error type: <class 'socket.error'>
None
2017-02-16 00:21:18,141 Traceback: ['  File "/home/uwslowcontrol/pi_db/pi_db.py", line 560, in <module>\n    saveValues(pi_data)\n', '  File "/home/uwslowcontrol/pi_db/pi_db.py", line 349, in saveValues\n    dbData.save(element)\n', '  File "/usr/lib/python2.6/site-packages/couchdb/client.py", line 439, in save\n    _, _, data = func(body=doc, **options)\n', '  File "/usr/lib/python2.6/site-packages/couchdb/http.py", line 545, in post_json\n    **params)\n', '  File "/usr/lib/python2.6/site-packages/couchdb/http.py", line 564, in _request_json\n    headers=headers, **params)\n', '  File "/usr/lib/python2.6/site-packages/couchdb/http.py", line 560, in _request\n    credentials=self.credentials)\n', '  File "/usr/lib/python2.6/site-packages/couchdb/http.py", line 330, in request\n    resp = _try_request_with_retries(iter(self.retry_delays))\n', '  File "/usr/lib/python2.6/site-packages/couchdb/http.py", line 290, in _try_request_with_retries\n    raise e\n']
None
2017-02-16 00:22:01,408 PI_DB SCRIPT INITIALIZING...
2017-02-16 02:49:27,193 Uncaught exception: [Errno 110] Connection timed out
None
2017-02-16 02:49:27,194 Error type: <class 'socket.error'>
None
2017-02-16 02:49:27,196 Traceback: ['  File "/home/uwslowcontrol/pi_db/pi_db.py", line 560, in <module>\n    saveValues(pi_data)\n', '  File "/home/uwslowcontrol/pi_db/pi_db.py", line 349, in saveValues\n    dbData.save(element)\n', '  File "/usr/lib/python2.6/site-packages/couchdb/client.py", line 439, in save\n    _, _, data = func(body=doc, **options)\n', '  File "/usr/lib/python2.6/site-packages/couchdb/http.py", line 545, in post_json\n    **params)\n', '  File "/usr/lib/python2.6/site-packages/couchdb/http.py", line 564, in _request_json\n    headers=headers, **params)\n', '  File "/usr/lib/python2.6/site-packages/couchdb/http.py", line 560, in _request\n    credentials=self.credentials)\n', '  File "/usr/lib/python2.6/site-packages/couchdb/http.py", line 330, in request\n    resp = _try_request_with_retries(iter(self.retry_delays))\n', '  File "/usr/lib/python2.6/site-packages/couchdb/http.py", line 290, in _try_request_with_retries\n    raise e\n']
None
2017-02-16 02:50:01,459 PI_DB SCRIPT INITIALIZING...
2017-02-16 17:31:10,935 Uncaught exception: [Errno 110] Connection timed out
None
2017-02-16 17:31:10,936 Error type: <class 'socket.error'>
None
2017-02-16 17:31:10,938 Traceback: ['  File "/home/uwslowcontrol/pi_db/pi_db.py", line 560, in <module>\n    saveValues(pi_data)\n', '  File "/home/uwslowcontrol/pi_db/pi_db.py", line 349, in saveValues\n    dbData.save(element)\n', '  File "/usr/lib/python2.6/site-packages/couchdb/client.py", line 439, in save\n    _, _, data = func(body=doc, **options)\n', '  File "/usr/lib/python2.6/site-packages/couchdb/http.py", line 545, in post_json\n    **params)\n', '  File "/usr/lib/python2.6/site-packages/couchdb/http.py", line 564, in _request_json\n    headers=headers, **params)\n', '  File "/usr/lib/python2.6/site-packages/couchdb/http.py", line 560, in _request\n    credentials=self.credentials)\n', '  File "/usr/lib/python2.6/site-packages/couchdb/http.py", line 330, in request\n    resp = _try_request_with_retries(iter(self.retry_delays))\n', '  File "/usr/lib/python2.6/site-packages/couchdb/http.py", line 290, in _try_request_with_retries\n    raise e\n']
None
2017-02-16 17:32:02,207 PI_DB SCRIPT INITIALIZING...
2017-02-22 00:27:41,140 Uncaught exception: [Errno 110] Connection timed out
None
2017-02-22 00:27:41,140 Error type: <class 'socket.error'>
None
2017-02-22 00:27:41,142 Traceback: ['  File "/home/uwslowcontrol/pi_db/pi_db.py", line 565, in <module>\n    saveAlarms(alarms_dict,alarms_last,channeldb)\n', '  File "/home/uwslowcontrol/pi_db/pi_db.py", line 453, in saveAlarms\n    num_rows = queryresults.total_rows\n', '  File "/usr/lib/python2.6/site-packages/couchdb/client.py", line 1217, in total_rows\n    self._fetch()\n', '  File "/usr/lib/python2.6/site-packages/couchdb/client.py", line 1191, in _fetch\n    data = self.view._exec(self.options)\n', '  File "/usr/lib/python2.6/site-packages/couchdb/client.py", line 1057, in _exec\n    _, _, data = _call_viewlike(self.resource, options)\n', '  File "/usr/lib/python2.6/site-packages/couchdb/client.py", line 1116, in _call_viewlike\n    return resource.get_json(**_encode_view_options(options))\n', '  File "/usr/lib/python2.6/site-packages/couchdb/http.py", line 541, in get_json\n    return self._request_json(\'GET\', path, headers=headers, **params)\n', '  File "/usr/lib/python2.6/site-packages/couchdb/http.py", line 564, in _request_json\n    headers=headers, **params)\n', '  File "/usr/lib/python2.6/site-packages/couchdb/http.py", line 560, in _request\n    credentials=self.credentials)\n', '  File "/usr/lib/python2.6/site-packages/couchdb/http.py", line 330, in request\n    resp = _try_request_with_retries(iter(self.retry_delays))\n', '  File "/usr/lib/python2.6/site-packages/couchdb/http.py", line 290, in _try_request_with_retries\n    raise e\n']
None
2017-02-22 00:28:01,410 PI_DB SCRIPT INITIALIZING...
2017-02-22 01:54:59,887 Uncaught exception: [Errno 110] Connection timed out
None
2017-02-22 01:54:59,888 Error type: <class 'socket.error'>
None
2017-02-22 01:54:59,890 Traceback: ['  File "/home/uwslowcontrol/pi_db/pi_db.py", line 560, in <module>\n    saveValues(pi_data)\n', '  File "/home/uwslowcontrol/pi_db/pi_db.py", line 349, in saveValues\n    dbData.save(element)\n', '  File "/usr/lib/python2.6/site-packages/couchdb/client.py", line 439, in save\n    _, _, data = func(body=doc, **options)\n', '  File "/usr/lib/python2.6/site-packages/couchdb/http.py", line 545, in post_json\n    **params)\n', '  File "/usr/lib/python2.6/site-packages/couchdb/http.py", line 564, in _request_json\n    headers=headers, **params)\n', '  File "/usr/lib/python2.6/site-packages/couchdb/http.py", line 560, in _request\n    credentials=self.credentials)\n', '  File "/usr/lib/python2.6/site-packages/couchdb/http.py", line 330, in request\n    resp = _try_request_with_retries(iter(self.retry_delays))\n', '  File "/usr/lib/python2.6/site-packages/couchdb/http.py", line 290, in _try_request_with_retries\n    raise e\n']
None
2017-02-22 01:55:02,148 PI_DB SCRIPT INITIALIZING...
2017-02-22 01:56:11,170 Uncaught exception: 'cavity_water_temp'
None
2017-02-22 01:56:11,170 Error type: <type 'exceptions.KeyError'>
None
2017-02-22 01:56:11,171 Traceback: ['  File "/home/uwslowcontrol/pi_db/pi_db.py", line 564, in <module>\n    PostAlarmServerAlarms(alarms_dict, alarms_last)\n', '  File "/home/uwslowcontrol/pi_db/pi_db.py", line 424, in PostAlarmServerAlarms\n    for channel in alarms_last[entry]:\n']
None
2017-02-22 01:57:01,428 PI_DB SCRIPT INITIALIZING...
2017-02-23 14:09:16,408 Uncaught exception: [Errno 110] Connection timed out
None
2017-02-23 14:09:16,409 Error type: <class 'socket.error'>
None
2017-02-23 14:09:16,410 Traceback: ['  File "/home/uwslowcontrol/pi_db/pi_db.py", line 560, in <module>\n    saveValues(pi_data)\n', '  File "/home/uwslowcontrol/pi_db/pi_db.py", line 349, in saveValues\n    dbData.save(element)\n', '  File "/usr/lib/python2.6/site-packages/couchdb/client.py", line 439, in save\n    _, _, data = func(body=doc, **options)\n', '  File "/usr/lib/python2.6/site-packages/couchdb/http.py", line 545, in post_json\n    **params)\n', '  File "/usr/lib/python2.6/site-packages/couchdb/http.py", line 564, in _request_json\n    headers=headers, **params)\n', '  File "/usr/lib/python2.6/site-packages/couchdb/http.py", line 560, in _request\n    credentials=self.credentials)\n', '  File "/usr/lib/python2.6/site-packages/couchdb/http.py", line 330, in request\n    resp = _try_request_with_retries(iter(self.retry_delays))\n', '  File "/usr/lib/python2.6/site-packages/couchdb/http.py", line 290, in _try_request_with_retries\n    raise e\n']
None
2017-02-23 14:10:01,678 PI_DB SCRIPT INITIALIZING...
2017-02-23 15:24:45,709 PI_DB SCRIPT INITIALIZING...
2017-02-23 15:25:02,539 Uncaught exception: 
None
2017-02-23 15:25:02,540 Error type: <type 'exceptions.KeyboardInterrupt'>
None
2017-02-23 15:25:02,540 Traceback: ['  File "pi_db.py", line 575, in <module>\n    time.sleep(wait_time)\n']
None
2017-02-23 15:25:06,931 PI_DB SCRIPT INITIALIZING...
2017-02-24 01:37:05,712 Uncaught exception: [Errno 110] Connection timed out
None
2017-02-24 01:37:05,713 Error type: <class 'socket.error'>
None
2017-02-24 01:37:05,715 Traceback: ['  File "/home/uwslowcontrol/pi_db/pi_db.py", line 570, in <module>\n    saveAlarms(alarms_dict,alarms_last,channeldb)\n', '  File "/home/uwslowcontrol/pi_db/pi_db.py", line 458, in saveAlarms\n    num_rows = queryresults.total_rows\n', '  File "/usr/lib/python2.6/site-packages/couchdb/client.py", line 1217, in total_rows\n    self._fetch()\n', '  File "/usr/lib/python2.6/site-packages/couchdb/client.py", line 1191, in _fetch\n    data = self.view._exec(self.options)\n', '  File "/usr/lib/python2.6/site-packages/couchdb/client.py", line 1057, in _exec\n    _, _, data = _call_viewlike(self.resource, options)\n', '  File "/usr/lib/python2.6/site-packages/couchdb/client.py", line 1116, in _call_viewlike\n    return resource.get_json(**_encode_view_options(options))\n', '  File "/usr/lib/python2.6/site-packages/couchdb/http.py", line 541, in get_json\n    return self._request_json(\'GET\', path, headers=headers, **params)\n', '  File "/usr/lib/python2.6/site-packages/couchdb/http.py", line 564, in _request_json\n    headers=headers, **params)\n', '  File "/usr/lib/python2.6/site-packages/couchdb/http.py", line 560, in _request\n    credentials=self.credentials)\n', '  File "/usr/lib/python2.6/site-packages/couchdb/http.py", line 330, in request\n    resp = _try_request_with_retries(iter(self.retry_delays))\n', '  File "/usr/lib/python2.6/site-packages/couchdb/http.py", line 290, in _try_request_with_retries\n    raise e\n']
None
2017-02-24 01:38:02,024 PI_DB SCRIPT INITIALIZING...
2017-02-24 14:35:45,283 PI_DB SCRIPT INITIALIZING...
2017-02-24 14:38:50,513 Uncaught exception: 
None
2017-02-24 14:38:50,513 Error type: <type 'exceptions.KeyboardInterrupt'>
None
2017-02-24 14:38:50,516 Traceback: ['  File "pi_db.py", line 579, in <module>\n    saveAlarms(alarms_dict,alarms_last,channeldb)\n', '  File "pi_db.py", line 458, in saveAlarms\n    num_rows = queryresults.total_rows\n', '  File "/usr/lib/python2.6/site-packages/couchdb/client.py", line 1217, in total_rows\n    self._fetch()\n', '  File "/usr/lib/python2.6/site-packages/couchdb/client.py", line 1191, in _fetch\n    data = self.view._exec(self.options)\n', '  File "/usr/lib/python2.6/site-packages/couchdb/client.py", line 1057, in _exec\n    _, _, data = _call_viewlike(self.resource, options)\n', '  File "/usr/lib/python2.6/site-packages/couchdb/client.py", line 1116, in _call_viewlike\n    return resource.get_json(**_encode_view_options(options))\n', '  File "/usr/lib/python2.6/site-packages/couchdb/http.py", line 541, in get_json\n    return self._request_json(\'GET\', path, headers=headers, **params)\n', '  File "/usr/lib/python2.6/site-packages/couchdb/http.py", line 564, in _request_json\n    headers=headers, **params)\n', '  File "/usr/lib/python2.6/site-packages/couchdb/http.py", line 560, in _request\n    credentials=self.credentials)\n', '  File "/usr/lib/python2.6/site-packages/couchdb/http.py", line 330, in request\n    resp = _try_request_with_retries(iter(self.retry_delays))\n', '  File "/usr/lib/python2.6/site-packages/couchdb/http.py", line 281, in _try_request_with_retries\n    return _try_request()\n', '  File "/usr/lib/python2.6/site-packages/couchdb/http.py", line 301, in _try_request\n    conn.endheaders()\n', '  File "/usr/lib/python2.6/site-packages/couchdb/http.py", line 63, in endheaders\n    self._send_output(message_body)\n', '  File "/usr/lib/python2.6/site-packages/couchdb/http.py", line 72, in _send_output\n    self.send(msg)\n', '  File "/usr/lib64/python2.6/httplib.py", line 790, in send\n    self.connect()\n', '  File "/usr/lib64/python2.6/httplib.py", line 771, in connect\n    self.timeout)\n', '  File "/usr/lib64/python2.6/socket.py", line 560, in create_connection\n    sock.connect(sa)\n', '  File "<string>", line 1, in connect\n']
None
2017-02-24 14:38:53,387 PI_DB SCRIPT INITIALIZING...
2017-02-27 20:17:14,309 Uncaught exception: [Errno 110] Connection timed out
None
2017-02-27 20:17:14,310 Error type: <class 'socket.error'>
None
2017-02-27 20:17:14,312 Traceback: ['  File "/home/uwslowcontrol/pi_db/pi_db.py", line 575, in <module>\n    channeldb = getChannelParameters(channeldb_last)\n', '  File "/home/uwslowcontrol/pi_db/pi_db.py", line 363, in getChannelParameters\n    channeldb = queryresults.rows[0].value\n', '  File "/usr/lib/python2.6/site-packages/couchdb/client.py", line 1205, in rows\n    self._fetch()\n', '  File "/usr/lib/python2.6/site-packages/couchdb/client.py", line 1191, in _fetch\n    data = self.view._exec(self.options)\n', '  File "/usr/lib/python2.6/site-packages/couchdb/client.py", line 1057, in _exec\n    _, _, data = _call_viewlike(self.resource, options)\n', '  File "/usr/lib/python2.6/site-packages/couchdb/client.py", line 1116, in _call_viewlike\n    return resource.get_json(**_encode_view_options(options))\n', '  File "/usr/lib/python2.6/site-packages/couchdb/http.py", line 541, in get_json\n    return self._request_json(\'GET\', path, headers=headers, **params)\n', '  File "/usr/lib/python2.6/site-packages/couchdb/http.py", line 564, in _request_json\n    headers=headers, **params)\n', '  File "/usr/lib/python2.6/site-packages/couchdb/http.py", line 560, in _request\n    credentials=self.credentials)\n', '  File "/usr/lib/python2.6/site-packages/couchdb/http.py", line 330, in request\n    resp = _try_request_with_retries(iter(self.retry_delays))\n', '  File "/usr/lib/python2.6/site-packages/couchdb/http.py", line 290, in _try_request_with_retries\n    raise e\n']
None
2017-02-27 20:18:01,833 PI_DB SCRIPT INITIALIZING...
2017-03-08 21:56:33,755 Uncaught exception: [Errno 110] Connection timed out
None
2017-03-08 21:56:33,756 Error type: <class 'socket.error'>
None
2017-03-08 21:56:33,758 Traceback: ['  File "/home/uwslowcontrol/pi_db/pi_db.py", line 575, in <module>\n    channeldb = getChannelParameters(channeldb_last)\n', '  File "/home/uwslowcontrol/pi_db/pi_db.py", line 363, in getChannelParameters\n    channeldb = queryresults.rows[0].value\n', '  File "/usr/lib/python2.6/site-packages/couchdb/client.py", line 1205, in rows\n    self._fetch()\n', '  File "/usr/lib/python2.6/site-packages/couchdb/client.py", line 1191, in _fetch\n    data = self.view._exec(self.options)\n', '  File "/usr/lib/python2.6/site-packages/couchdb/client.py", line 1057, in _exec\n    _, _, data = _call_viewlike(self.resource, options)\n', '  File "/usr/lib/python2.6/site-packages/couchdb/client.py", line 1116, in _call_viewlike\n    return resource.get_json(**_encode_view_options(options))\n', '  File "/usr/lib/python2.6/site-packages/couchdb/http.py", line 541, in get_json\n    return self._request_json(\'GET\', path, headers=headers, **params)\n', '  File "/usr/lib/python2.6/site-packages/couchdb/http.py", line 564, in _request_json\n    headers=headers, **params)\n', '  File "/usr/lib/python2.6/site-packages/couchdb/http.py", line 560, in _request\n    credentials=self.credentials)\n', '  File "/usr/lib/python2.6/site-packages/couchdb/http.py", line 330, in request\n    resp = _try_request_with_retries(iter(self.retry_delays))\n', '  File "/usr/lib/python2.6/site-packages/couchdb/http.py", line 290, in _try_request_with_retries\n    raise e\n']
None
2017-03-08 21:57:02,050 PI_DB SCRIPT INITIALIZING...
2017-03-09 01:10:26,797 FAILED TO SAVE 1 MIN ENTRYFOR THIS MINUTE.  ERROR: [Errno 110] Connection timed out
Traceback (most recent call last):
  File "/home/uwslowcontrol/pi_db/pi_db.py", line 351, in saveValues
    dbData.save(element)
  File "/usr/lib/python2.6/site-packages/couchdb/client.py", line 439, in save
    _, _, data = func(body=doc, **options)
  File "/usr/lib/python2.6/site-packages/couchdb/http.py", line 545, in post_json
    **params)
  File "/usr/lib/python2.6/site-packages/couchdb/http.py", line 564, in _request_json
    headers=headers, **params)
  File "/usr/lib/python2.6/site-packages/couchdb/http.py", line 560, in _request
    credentials=self.credentials)
  File "/usr/lib/python2.6/site-packages/couchdb/http.py", line 330, in request
    resp = _try_request_with_retries(iter(self.retry_delays))
  File "/usr/lib/python2.6/site-packages/couchdb/http.py", line 290, in _try_request_with_retries
    raise e
error: [Errno 110] Connection timed out
2017-03-10 01:15:46,873 Uncaught exception: [Errno 110] Connection timed out
None
2017-03-10 01:15:46,874 Error type: <class 'socket.error'>
None
2017-03-10 01:15:46,874 Traceback: ['  File "/home/uwslowcontrol/pi_db/pi_db.py", line 579, in <module>\n    saveAlarms(alarms_dict,alarms_last,channeldb)\n', '  File "/home/uwslowcontrol/pi_db/pi_db.py", line 458, in saveAlarms\n    num_rows = queryresults.total_rows\n', '  File "/usr/lib/python2.6/site-packages/couchdb/client.py", line 1217, in total_rows\n    self._fetch()\n', '  File "/usr/lib/python2.6/site-packages/couchdb/client.py", line 1191, in _fetch\n    data = self.view._exec(self.options)\n', '  File "/usr/lib/python2.6/site-packages/couchdb/client.py", line 1057, in _exec\n    _, _, data = _call_viewlike(self.resource, options)\n', '  File "/usr/lib/python2.6/site-packages/couchdb/client.py", line 1116, in _call_viewlike\n    return resource.get_json(**_encode_view_options(options))\n', '  File "/usr/lib/python2.6/site-packages/couchdb/http.py", line 541, in get_json\n    return self._request_json(\'GET\', path, headers=headers, **params)\n', '  File "/usr/lib/python2.6/site-packages/couchdb/http.py", line 564, in _request_json\n    headers=headers, **params)\n', '  File "/usr/lib/python2.6/site-packages/couchdb/http.py", line 560, in _request\n    credentials=self.credentials)\n', '  File "/usr/lib/python2.6/site-packages/couchdb/http.py", line 330, in request\n    resp = _try_request_with_retries(iter(self.retry_delays))\n', '  File "/usr/lib/python2.6/site-packages/couchdb/http.py", line 290, in _try_request_with_retries\n    raise e\n']
None
2017-03-10 01:16:02,141 PI_DB SCRIPT INITIALIZING...
2017-03-10 14:43:16,519 Uncaught exception: [Errno 110] Connection timed out
None
2017-03-10 14:43:16,520 Error type: <class 'socket.error'>
None
2017-03-10 14:43:16,522 Traceback: ['  File "/home/uwslowcontrol/pi_db/pi_db.py", line 575, in <module>\n    channeldb = getChannelParameters(channeldb_last)\n', '  File "/home/uwslowcontrol/pi_db/pi_db.py", line 363, in getChannelParameters\n    channeldb = queryresults.rows[0].value\n', '  File "/usr/lib/python2.6/site-packages/couchdb/client.py", line 1205, in rows\n    self._fetch()\n', '  File "/usr/lib/python2.6/site-packages/couchdb/client.py", line 1191, in _fetch\n    data = self.view._exec(self.options)\n', '  File "/usr/lib/python2.6/site-packages/couchdb/client.py", line 1057, in _exec\n    _, _, data = _call_viewlike(self.resource, options)\n', '  File "/usr/lib/python2.6/site-packages/couchdb/client.py", line 1116, in _call_viewlike\n    return resource.get_json(**_encode_view_options(options))\n', '  File "/usr/lib/python2.6/site-packages/couchdb/http.py", line 541, in get_json\n    return self._request_json(\'GET\', path, headers=headers, **params)\n', '  File "/usr/lib/python2.6/site-packages/couchdb/http.py", line 564, in _request_json\n    headers=headers, **params)\n', '  File "/usr/lib/python2.6/site-packages/couchdb/http.py", line 560, in _request\n    credentials=self.credentials)\n', '  File "/usr/lib/python2.6/site-packages/couchdb/http.py", line 330, in request\n    resp = _try_request_with_retries(iter(self.retry_delays))\n', '  File "/usr/lib/python2.6/site-packages/couchdb/http.py", line 290, in _try_request_with_retries\n    raise e\n']
None
2017-03-10 14:44:01,798 PI_DB SCRIPT INITIALIZING...
2017-03-17 14:10:17,159 PI_DB SCRIPT INITIALIZING...
2017-03-17 14:15:00,877 PI_DB SCRIPT INITIALIZING...
2017-03-17 14:15:25,217 Uncaught exception: 
None
2017-03-17 14:15:25,218 Error type: <type 'exceptions.KeyboardInterrupt'>
None
2017-03-17 14:15:25,218 Traceback: ['  File "pi_db.py", line 584, in <module>\n    time.sleep(wait_time)\n']
None
2017-03-17 14:15:53,105 PI_DB SCRIPT INITIALIZING...
2017-03-17 15:06:38,849 Uncaught exception: 
None
2017-03-17 15:06:38,850 Error type: <type 'exceptions.KeyboardInterrupt'>
None
2017-03-17 15:06:38,851 Traceback: ['  File "pi_db.py", line 584, in <module>\n    time.sleep(wait_time)\n']
None
2017-03-17 15:06:43,149 PI_DB SCRIPT INITIALIZING...
2017-03-17 15:07:54,669 Uncaught exception: [Errno 5] Input/output error
None
2017-03-17 15:07:54,669 Error type: <type 'exceptions.IOError'>
None
2017-03-17 15:07:54,670 Traceback: ['  File "/home/uwslowcontrol/pi_db/pi_db.py", line 573, in <module>\n    print pi_data\n']
None
2017-03-17 15:08:01,971 PI_DB SCRIPT INITIALIZING...
2017-03-19 01:20:01,057 FAILED TO SAVE 1 MIN ENTRYFOR THIS MINUTE.  ERROR: [Errno 110] Connection timed out
Traceback (most recent call last):
  File "/home/uwslowcontrol/pi_db/pi_db.py", line 351, in saveValues
    dbData.save(element)
  File "/usr/lib/python2.6/site-packages/couchdb/client.py", line 439, in save
    _, _, data = func(body=doc, **options)
  File "/usr/lib/python2.6/site-packages/couchdb/http.py", line 545, in post_json
    **params)
  File "/usr/lib/python2.6/site-packages/couchdb/http.py", line 564, in _request_json
    headers=headers, **params)
  File "/usr/lib/python2.6/site-packages/couchdb/http.py", line 560, in _request
    credentials=self.credentials)
  File "/usr/lib/python2.6/site-packages/couchdb/http.py", line 330, in request
    resp = _try_request_with_retries(iter(self.retry_delays))
  File "/usr/lib/python2.6/site-packages/couchdb/http.py", line 290, in _try_request_with_retries
    raise e
error: [Errno 110] Connection timed out
2017-03-19 08:44:42,175 Uncaught exception: [Errno 110] Connection timed out
None
2017-03-19 08:44:42,175 Error type: <class 'socket.error'>
None
2017-03-19 08:44:42,176 Traceback: ['  File "/home/uwslowcontrol/pi_db/pi_db.py", line 579, in <module>\n    saveAlarms(alarms_dict,alarms_last,channeldb)\n', '  File "/home/uwslowcontrol/pi_db/pi_db.py", line 458, in saveAlarms\n    num_rows = queryresults.total_rows\n', '  File "/usr/lib/python2.6/site-packages/couchdb/client.py", line 1217, in total_rows\n    self._fetch()\n', '  File "/usr/lib/python2.6/site-packages/couchdb/client.py", line 1191, in _fetch\n    data = self.view._exec(self.options)\n', '  File "/usr/lib/python2.6/site-packages/couchdb/client.py", line 1057, in _exec\n    _, _, data = _call_viewlike(self.resource, options)\n', '  File "/usr/lib/python2.6/site-packages/couchdb/client.py", line 1116, in _call_viewlike\n    return resource.get_json(**_encode_view_options(options))\n', '  File "/usr/lib/python2.6/site-packages/couchdb/http.py", line 541, in get_json\n    return self._request_json(\'GET\', path, headers=headers, **params)\n', '  File "/usr/lib/python2.6/site-packages/couchdb/http.py", line 564, in _request_json\n    headers=headers, **params)\n', '  File "/usr/lib/python2.6/site-packages/couchdb/http.py", line 560, in _request\n    credentials=self.credentials)\n', '  File "/usr/lib/python2.6/site-packages/couchdb/http.py", line 330, in request\n    resp = _try_request_with_retries(iter(self.retry_delays))\n', '  File "/usr/lib/python2.6/site-packages/couchdb/http.py", line 290, in _try_request_with_retries\n    raise e\n']
None
2017-03-19 08:45:01,428 PI_DB SCRIPT INITIALIZING...
2017-03-19 08:47:13,703 Uncaught exception: 'cavity_water_temp'
None
2017-03-19 08:47:13,703 Error type: <type 'exceptions.KeyError'>
None
2017-03-19 08:47:13,704 Traceback: ['  File "/home/uwslowcontrol/pi_db/pi_db.py", line 578, in <module>\n    PostAlarmServerAlarms(alarms_dict, alarms_last)\n', '  File "/home/uwslowcontrol/pi_db/pi_db.py", line 429, in PostAlarmServerAlarms\n    for channel in alarms_last[entry]:\n']
None
2017-03-19 08:48:01,971 PI_DB SCRIPT INITIALIZING...
2017-03-19 13:08:11,669 FAILED TO SAVE 1 MIN ENTRYFOR THIS MINUTE.  ERROR: [Errno 110] Connection timed out
Traceback (most recent call last):
  File "/home/uwslowcontrol/pi_db/pi_db.py", line 351, in saveValues
    dbData.save(element)
  File "/usr/lib/python2.6/site-packages/couchdb/client.py", line 439, in save
    _, _, data = func(body=doc, **options)
  File "/usr/lib/python2.6/site-packages/couchdb/http.py", line 545, in post_json
    **params)
  File "/usr/lib/python2.6/site-packages/couchdb/http.py", line 564, in _request_json
    headers=headers, **params)
  File "/usr/lib/python2.6/site-packages/couchdb/http.py", line 560, in _request
    credentials=self.credentials)
  File "/usr/lib/python2.6/site-packages/couchdb/http.py", line 330, in request
    resp = _try_request_with_retries(iter(self.retry_delays))
  File "/usr/lib/python2.6/site-packages/couchdb/http.py", line 290, in _try_request_with_retries
    raise e
error: [Errno 110] Connection timed out
2017-03-19 13:10:19,154 Uncaught exception: [Errno 110] Connection timed out
None
2017-03-19 13:10:19,154 Error type: <class 'socket.error'>
None
2017-03-19 13:10:19,155 Traceback: ['  File "/home/uwslowcontrol/pi_db/pi_db.py", line 579, in <module>\n    saveAlarms(alarms_dict,alarms_last,channeldb)\n', '  File "/home/uwslowcontrol/pi_db/pi_db.py", line 458, in saveAlarms\n    num_rows = queryresults.total_rows\n', '  File "/usr/lib/python2.6/site-packages/couchdb/client.py", line 1217, in total_rows\n    self._fetch()\n', '  File "/usr/lib/python2.6/site-packages/couchdb/client.py", line 1191, in _fetch\n    data = self.view._exec(self.options)\n', '  File "/usr/lib/python2.6/site-packages/couchdb/client.py", line 1057, in _exec\n    _, _, data = _call_viewlike(self.resource, options)\n', '  File "/usr/lib/python2.6/site-packages/couchdb/client.py", line 1116, in _call_viewlike\n    return resource.get_json(**_encode_view_options(options))\n', '  File "/usr/lib/python2.6/site-packages/couchdb/http.py", line 541, in get_json\n    return self._request_json(\'GET\', path, headers=headers, **params)\n', '  File "/usr/lib/python2.6/site-packages/couchdb/http.py", line 564, in _request_json\n    headers=headers, **params)\n', '  File "/usr/lib/python2.6/site-packages/couchdb/http.py", line 560, in _request\n    credentials=self.credentials)\n', '  File "/usr/lib/python2.6/site-packages/couchdb/http.py", line 330, in request\n    resp = _try_request_with_retries(iter(self.retry_delays))\n', '  File "/usr/lib/python2.6/site-packages/couchdb/http.py", line 290, in _try_request_with_retries\n    raise e\n']
None
2017-03-19 13:11:01,421 PI_DB SCRIPT INITIALIZING...
2017-03-19 15:29:20,802 Uncaught exception: [Errno 110] Connection timed out
None
2017-03-19 15:29:20,803 Error type: <class 'socket.error'>
None
2017-03-19 15:29:20,805 Traceback: ['  File "/home/uwslowcontrol/pi_db/pi_db.py", line 579, in <module>\n    saveAlarms(alarms_dict,alarms_last,channeldb)\n', '  File "/home/uwslowcontrol/pi_db/pi_db.py", line 458, in saveAlarms\n    num_rows = queryresults.total_rows\n', '  File "/usr/lib/python2.6/site-packages/couchdb/client.py", line 1217, in total_rows\n    self._fetch()\n', '  File "/usr/lib/python2.6/site-packages/couchdb/client.py", line 1191, in _fetch\n    data = self.view._exec(self.options)\n', '  File "/usr/lib/python2.6/site-packages/couchdb/client.py", line 1057, in _exec\n    _, _, data = _call_viewlike(self.resource, options)\n', '  File "/usr/lib/python2.6/site-packages/couchdb/client.py", line 1116, in _call_viewlike\n    return resource.get_json(**_encode_view_options(options))\n', '  File "/usr/lib/python2.6/site-packages/couchdb/http.py", line 541, in get_json\n    return self._request_json(\'GET\', path, headers=headers, **params)\n', '  File "/usr/lib/python2.6/site-packages/couchdb/http.py", line 564, in _request_json\n    headers=headers, **params)\n', '  File "/usr/lib/python2.6/site-packages/couchdb/http.py", line 560, in _request\n    credentials=self.credentials)\n', '  File "/usr/lib/python2.6/site-packages/couchdb/http.py", line 330, in request\n    resp = _try_request_with_retries(iter(self.retry_delays))\n', '  File "/usr/lib/python2.6/site-packages/couchdb/http.py", line 290, in _try_request_with_retries\n    raise e\n']
None
2017-03-19 15:30:02,073 PI_DB SCRIPT INITIALIZING...
2017-03-19 15:32:24,307 Uncaught exception: [Errno 110] Connection timed out
None
2017-03-19 15:32:24,308 Error type: <class 'socket.error'>
None
2017-03-19 15:32:24,310 Traceback: ['  File "/home/uwslowcontrol/pi_db/pi_db.py", line 579, in <module>\n    saveAlarms(alarms_dict,alarms_last,channeldb)\n', '  File "/home/uwslowcontrol/pi_db/pi_db.py", line 458, in saveAlarms\n    num_rows = queryresults.total_rows\n', '  File "/usr/lib/python2.6/site-packages/couchdb/client.py", line 1217, in total_rows\n    self._fetch()\n', '  File "/usr/lib/python2.6/site-packages/couchdb/client.py", line 1191, in _fetch\n    data = self.view._exec(self.options)\n', '  File "/usr/lib/python2.6/site-packages/couchdb/client.py", line 1057, in _exec\n    _, _, data = _call_viewlike(self.resource, options)\n', '  File "/usr/lib/python2.6/site-packages/couchdb/client.py", line 1116, in _call_viewlike\n    return resource.get_json(**_encode_view_options(options))\n', '  File "/usr/lib/python2.6/site-packages/couchdb/http.py", line 541, in get_json\n    return self._request_json(\'GET\', path, headers=headers, **params)\n', '  File "/usr/lib/python2.6/site-packages/couchdb/http.py", line 564, in _request_json\n    headers=headers, **params)\n', '  File "/usr/lib/python2.6/site-packages/couchdb/http.py", line 560, in _request\n    credentials=self.credentials)\n', '  File "/usr/lib/python2.6/site-packages/couchdb/http.py", line 330, in request\n    resp = _try_request_with_retries(iter(self.retry_delays))\n', '  File "/usr/lib/python2.6/site-packages/couchdb/http.py", line 290, in _try_request_with_retries\n    raise e\n']
None
2017-03-19 15:33:01,582 PI_DB SCRIPT INITIALIZING...
2017-03-19 15:35:08,648 Uncaught exception: [Errno 110] Connection timed out
None
2017-03-19 15:35:08,649 Error type: <class 'socket.error'>
None
2017-03-19 15:35:08,651 Traceback: ['  File "/home/uwslowcontrol/pi_db/pi_db.py", line 562, in <module>\n    alarms_last = getPastAlarms()\n', '  File "/home/uwslowcontrol/pi_db/pi_db.py", line 442, in getPastAlarms\n    num_rows = queryresults.total_rows\n', '  File "/usr/lib/python2.6/site-packages/couchdb/client.py", line 1217, in total_rows\n    self._fetch()\n', '  File "/usr/lib/python2.6/site-packages/couchdb/client.py", line 1191, in _fetch\n    data = self.view._exec(self.options)\n', '  File "/usr/lib/python2.6/site-packages/couchdb/client.py", line 1057, in _exec\n    _, _, data = _call_viewlike(self.resource, options)\n', '  File "/usr/lib/python2.6/site-packages/couchdb/client.py", line 1116, in _call_viewlike\n    return resource.get_json(**_encode_view_options(options))\n', '  File "/usr/lib/python2.6/site-packages/couchdb/http.py", line 541, in get_json\n    return self._request_json(\'GET\', path, headers=headers, **params)\n', '  File "/usr/lib/python2.6/site-packages/couchdb/http.py", line 564, in _request_json\n    headers=headers, **params)\n', '  File "/usr/lib/python2.6/site-packages/couchdb/http.py", line 560, in _request\n    credentials=self.credentials)\n', '  File "/usr/lib/python2.6/site-packages/couchdb/http.py", line 330, in request\n    resp = _try_request_with_retries(iter(self.retry_delays))\n', '  File "/usr/lib/python2.6/site-packages/couchdb/http.py", line 290, in _try_request_with_retries\n    raise e\n']
None
2017-03-19 15:36:01,911 PI_DB SCRIPT INITIALIZING...
2017-03-19 17:46:57,186 FAILED TO SAVE 1 MIN ENTRYFOR THIS MINUTE.  ERROR: [Errno 110] Connection timed out
Traceback (most recent call last):
  File "/home/uwslowcontrol/pi_db/pi_db.py", line 351, in saveValues
    dbData.save(element)
  File "/usr/lib/python2.6/site-packages/couchdb/client.py", line 439, in save
    _, _, data = func(body=doc, **options)
  File "/usr/lib/python2.6/site-packages/couchdb/http.py", line 545, in post_json
    **params)
  File "/usr/lib/python2.6/site-packages/couchdb/http.py", line 564, in _request_json
    headers=headers, **params)
  File "/usr/lib/python2.6/site-packages/couchdb/http.py", line 560, in _request
    credentials=self.credentials)
  File "/usr/lib/python2.6/site-packages/couchdb/http.py", line 330, in request
    resp = _try_request_with_retries(iter(self.retry_delays))
  File "/usr/lib/python2.6/site-packages/couchdb/http.py", line 290, in _try_request_with_retries
    raise e
error: [Errno 110] Connection timed out
2017-03-19 22:33:33,080 Uncaught exception: [Errno 110] Connection timed out
None
2017-03-19 22:33:33,081 Error type: <class 'socket.error'>
None
2017-03-19 22:33:33,082 Traceback: ['  File "/home/uwslowcontrol/pi_db/pi_db.py", line 575, in <module>\n    channeldb = getChannelParameters(channeldb_last)\n', '  File "/home/uwslowcontrol/pi_db/pi_db.py", line 363, in getChannelParameters\n    channeldb = queryresults.rows[0].value\n', '  File "/usr/lib/python2.6/site-packages/couchdb/client.py", line 1205, in rows\n    self._fetch()\n', '  File "/usr/lib/python2.6/site-packages/couchdb/client.py", line 1191, in _fetch\n    data = self.view._exec(self.options)\n', '  File "/usr/lib/python2.6/site-packages/couchdb/client.py", line 1057, in _exec\n    _, _, data = _call_viewlike(self.resource, options)\n', '  File "/usr/lib/python2.6/site-packages/couchdb/client.py", line 1116, in _call_viewlike\n    return resource.get_json(**_encode_view_options(options))\n', '  File "/usr/lib/python2.6/site-packages/couchdb/http.py", line 541, in get_json\n    return self._request_json(\'GET\', path, headers=headers, **params)\n', '  File "/usr/lib/python2.6/site-packages/couchdb/http.py", line 564, in _request_json\n    headers=headers, **params)\n', '  File "/usr/lib/python2.6/site-packages/couchdb/http.py", line 560, in _request\n    credentials=self.credentials)\n', '  File "/usr/lib/python2.6/site-packages/couchdb/http.py", line 330, in request\n    resp = _try_request_with_retries(iter(self.retry_delays))\n', '  File "/usr/lib/python2.6/site-packages/couchdb/http.py", line 290, in _try_request_with_retries\n    raise e\n']
None
2017-03-19 22:34:01,357 PI_DB SCRIPT INITIALIZING...
2017-03-19 22:35:10,456 Uncaught exception: 'cavity_water_temp'
None
2017-03-19 22:35:10,456 Error type: <type 'exceptions.KeyError'>
None
2017-03-19 22:35:10,457 Traceback: ['  File "/home/uwslowcontrol/pi_db/pi_db.py", line 578, in <module>\n    PostAlarmServerAlarms(alarms_dict, alarms_last)\n', '  File "/home/uwslowcontrol/pi_db/pi_db.py", line 429, in PostAlarmServerAlarms\n    for channel in alarms_last[entry]:\n']
None
2017-03-19 22:36:01,718 PI_DB SCRIPT INITIALIZING...
2017-03-20 09:23:12,467 Uncaught exception: [Errno 110] Connection timed out
None
2017-03-20 09:23:12,468 Error type: <class 'socket.error'>
None
2017-03-20 09:23:12,470 Traceback: ['  File "/home/uwslowcontrol/pi_db/pi_db.py", line 575, in <module>\n    channeldb = getChannelParameters(channeldb_last)\n', '  File "/home/uwslowcontrol/pi_db/pi_db.py", line 363, in getChannelParameters\n    channeldb = queryresults.rows[0].value\n', '  File "/usr/lib/python2.6/site-packages/couchdb/client.py", line 1205, in rows\n    self._fetch()\n', '  File "/usr/lib/python2.6/site-packages/couchdb/client.py", line 1191, in _fetch\n    data = self.view._exec(self.options)\n', '  File "/usr/lib/python2.6/site-packages/couchdb/client.py", line 1057, in _exec\n    _, _, data = _call_viewlike(self.resource, options)\n', '  File "/usr/lib/python2.6/site-packages/couchdb/client.py", line 1116, in _call_viewlike\n    return resource.get_json(**_encode_view_options(options))\n', '  File "/usr/lib/python2.6/site-packages/couchdb/http.py", line 541, in get_json\n    return self._request_json(\'GET\', path, headers=headers, **params)\n', '  File "/usr/lib/python2.6/site-packages/couchdb/http.py", line 564, in _request_json\n    headers=headers, **params)\n', '  File "/usr/lib/python2.6/site-packages/couchdb/http.py", line 560, in _request\n    credentials=self.credentials)\n', '  File "/usr/lib/python2.6/site-packages/couchdb/http.py", line 330, in request\n    resp = _try_request_with_retries(iter(self.retry_delays))\n', '  File "/usr/lib/python2.6/site-packages/couchdb/http.py", line 290, in _try_request_with_retries\n    raise e\n']
None
2017-03-20 09:24:01,735 PI_DB SCRIPT INITIALIZING...
2017-03-20 15:44:51,019 PI_DB SCRIPT INITIALIZING...
2017-03-20 15:45:10,067 Uncaught exception: 
None
2017-03-20 15:45:10,068 Error type: <type 'exceptions.KeyboardInterrupt'>
None
2017-03-20 15:45:10,071 Traceback: ['  File "pi_db.py", line 607, in <module>\n    alarms_last = getPastAlarms()\n', '  File "pi_db.py", line 467, in getPastAlarms\n    num_rows = queryresults.total_rows\n', '  File "/usr/lib/python2.6/site-packages/couchdb/client.py", line 1217, in total_rows\n    self._fetch()\n', '  File "/usr/lib/python2.6/site-packages/couchdb/client.py", line 1191, in _fetch\n    data = self.view._exec(self.options)\n', '  File "/usr/lib/python2.6/site-packages/couchdb/client.py", line 1057, in _exec\n    _, _, data = _call_viewlike(self.resource, options)\n', '  File "/usr/lib/python2.6/site-packages/couchdb/client.py", line 1116, in _call_viewlike\n    return resource.get_json(**_encode_view_options(options))\n', '  File "/usr/lib/python2.6/site-packages/couchdb/http.py", line 541, in get_json\n    return self._request_json(\'GET\', path, headers=headers, **params)\n', '  File "/usr/lib/python2.6/site-packages/couchdb/http.py", line 564, in _request_json\n    headers=headers, **params)\n', '  File "/usr/lib/python2.6/site-packages/couchdb/http.py", line 560, in _request\n    credentials=self.credentials)\n', '  File "/usr/lib/python2.6/site-packages/couchdb/http.py", line 330, in request\n    resp = _try_request_with_retries(iter(self.retry_delays))\n', '  File "/usr/lib/python2.6/site-packages/couchdb/http.py", line 281, in _try_request_with_retries\n    return _try_request()\n', '  File "/usr/lib/python2.6/site-packages/couchdb/http.py", line 301, in _try_request\n    conn.endheaders()\n', '  File "/usr/lib/python2.6/site-packages/couchdb/http.py", line 63, in endheaders\n    self._send_output(message_body)\n', '  File "/usr/lib/python2.6/site-packages/couchdb/http.py", line 72, in _send_output\n    self.send(msg)\n', '  File "/usr/lib64/python2.6/httplib.py", line 790, in send\n    self.connect()\n', '  File "/usr/lib64/python2.6/httplib.py", line 771, in connect\n    self.timeout)\n', '  File "/usr/lib64/python2.6/socket.py", line 553, in create_connection\n    for res in getaddrinfo(host, port, 0, SOCK_STREAM):\n']
None
2017-03-20 15:52:58,153 PI_DB SCRIPT INITIALIZING...
2017-03-20 15:53:04,542 Uncaught exception: 
None
2017-03-20 15:53:04,543 Error type: <type 'exceptions.KeyboardInterrupt'>
None
2017-03-20 15:53:04,547 Traceback: ['  File "pi_db.py", line 607, in <module>\n    alarms_last = getPastAlarms()\n', '  File "pi_db.py", line 467, in getPastAlarms\n    num_rows = queryresults.total_rows\n', '  File "/usr/lib/python2.6/site-packages/couchdb/client.py", line 1217, in total_rows\n    self._fetch()\n', '  File "/usr/lib/python2.6/site-packages/couchdb/client.py", line 1191, in _fetch\n    data = self.view._exec(self.options)\n', '  File "/usr/lib/python2.6/site-packages/couchdb/client.py", line 1057, in _exec\n    _, _, data = _call_viewlike(self.resource, options)\n', '  File "/usr/lib/python2.6/site-packages/couchdb/client.py", line 1116, in _call_viewlike\n    return resource.get_json(**_encode_view_options(options))\n', '  File "/usr/lib/python2.6/site-packages/couchdb/http.py", line 541, in get_json\n    return self._request_json(\'GET\', path, headers=headers, **params)\n', '  File "/usr/lib/python2.6/site-packages/couchdb/http.py", line 566, in _request_json\n    data = json.decode(data.read().decode(\'utf-8\'))\n', '  File "/usr/lib/python2.6/site-packages/couchdb/json.py", line 56, in decode\n    return _decode(string)\n', '  File "/usr/lib/python2.6/site-packages/couchdb/json.py", line 132, in _decode\n    return loads(string_)\n', '  File "/usr/lib64/python2.6/json/__init__.py", line 307, in loads\n    return _default_decoder.decode(s)\n', '  File "/usr/lib64/python2.6/json/decoder.py", line 319, in decode\n    obj, end = self.raw_decode(s, idx=_w(s, 0).end())\n', '  File "/usr/lib64/python2.6/json/decoder.py", line 336, in raw_decode\n    obj, end = self._scanner.iterscan(s, **kw).next()\n', '  File "/usr/lib64/python2.6/json/scanner.py", line 55, in iterscan\n    rval, next_pos = action(m, context)\n', '  File "/usr/lib64/python2.6/json/decoder.py", line 183, in JSONObject\n    value, end = iterscan(s, idx=end, context=context).next()\n', '  File "/usr/lib64/python2.6/json/scanner.py", line 55, in iterscan\n    rval, next_pos = action(m, context)\n', '  File "/usr/lib64/python2.6/json/decoder.py", line 217, in JSONArray\n    value, end = iterscan(s, idx=end, context=context).next()\n', '  File "/usr/lib64/python2.6/json/scanner.py", line 55, in iterscan\n    rval, next_pos = action(m, context)\n', '  File "/usr/lib64/python2.6/json/decoder.py", line 188, in JSONObject\n    nextchar = s[end:end + 1]\n']
None
2017-03-20 15:53:27,822 PI_DB SCRIPT INITIALIZING...
2017-03-20 16:00:44,481 PI_DB SCRIPT INITIALIZING...
2017-03-20 16:01:12,298 Uncaught exception: 
None
2017-03-20 16:01:12,298 Error type: <type 'exceptions.KeyboardInterrupt'>
None
2017-03-20 16:01:12,301 Traceback: ['  File "pi_db.py", line 607, in <module>\n    alarms_last = getPastAlarms()\n', '  File "pi_db.py", line 467, in getPastAlarms\n    num_rows = queryresults.total_rows\n', '  File "/usr/lib/python2.6/site-packages/couchdb/client.py", line 1217, in total_rows\n    self._fetch()\n', '  File "/usr/lib/python2.6/site-packages/couchdb/client.py", line 1191, in _fetch\n    data = self.view._exec(self.options)\n', '  File "/usr/lib/python2.6/site-packages/couchdb/client.py", line 1057, in _exec\n    _, _, data = _call_viewlike(self.resource, options)\n', '  File "/usr/lib/python2.6/site-packages/couchdb/client.py", line 1116, in _call_viewlike\n    return resource.get_json(**_encode_view_options(options))\n', '  File "/usr/lib/python2.6/site-packages/couchdb/http.py", line 541, in get_json\n    return self._request_json(\'GET\', path, headers=headers, **params)\n', '  File "/usr/lib/python2.6/site-packages/couchdb/http.py", line 564, in _request_json\n    headers=headers, **params)\n', '  File "/usr/lib/python2.6/site-packages/couchdb/http.py", line 560, in _request\n    credentials=self.credentials)\n', '  File "/usr/lib/python2.6/site-packages/couchdb/http.py", line 330, in request\n    resp = _try_request_with_retries(iter(self.retry_delays))\n', '  File "/usr/lib/python2.6/site-packages/couchdb/http.py", line 281, in _try_request_with_retries\n    return _try_request()\n', '  File "/usr/lib/python2.6/site-packages/couchdb/http.py", line 301, in _try_request\n    conn.endheaders()\n', '  File "/usr/lib/python2.6/site-packages/couchdb/http.py", line 63, in endheaders\n    self._send_output(message_body)\n', '  File "/usr/lib/python2.6/site-packages/couchdb/http.py", line 72, in _send_output\n    self.send(msg)\n', '  File "/usr/lib64/python2.6/httplib.py", line 790, in send\n    self.connect()\n', '  File "/usr/lib64/python2.6/httplib.py", line 771, in connect\n    self.timeout)\n', '  File "/usr/lib64/python2.6/socket.py", line 560, in create_connection\n    sock.connect(sa)\n', '  File "<string>", line 1, in connect\n']
None
2017-03-20 16:06:47,428 PI_DB SCRIPT INITIALIZING...
2017-03-20 16:10:27,649 Uncaught exception: 
None
2017-03-20 16:10:27,649 Error type: <type 'exceptions.KeyboardInterrupt'>
None
2017-03-20 16:10:27,650 Traceback: ['  File "pi_db.py", line 631, in <module>\n    time.sleep(wait_time)\n']
None
2017-03-20 16:10:38,686 PI_DB SCRIPT INITIALIZING...
2017-03-20 16:12:10,196 PI_DB SCRIPT INITIALIZING...
2017-03-20 16:15:08,998 PI_DB SCRIPT INITIALIZING...
